Workbook
Name _DAT10: [1]May!$I$2:$I$4
Name _DAT2: [1]May!#REF!
Name _DAT2: [1]May!#REF!
Name _DAT8: [1]May!$G$2:$G$4
Name _DAT9: [1]May!$H$2:$H$4
Name DATA1: #REF!
Name DATA10: #REF!
Name DATA11: #REF!
Name DATA12: #REF!
Name DATA13: #REF!
Name DATA14: #REF!
Name DATA15: #REF!
Name DATA16: #REF!
Name DATA17: #REF!
Name DATA18: #REF!
Name DATA18: #REF!
Name DATA2: #REF!
Name DATA3: #REF!
Name DATA4: #REF!
Name DATA5: #REF!
Name DATA6: #REF!
Name DATA7: #REF!
Name DATA8: #REF!
Name DATA9: #REF!
Name DF_GRID_1: #REF!
Name DF_GRID_1: #REF!
Name SAPCrosstab1: details!$A$5:$AB$422
Name TEST0: #REF!
Name TEST1: #REF!
Name TEST1: #REF!
Name TEST2: #REF!
Name TEST2: #REF!
Name TESTHKEY: #REF!
Name TESTHKEY: #REF!
Name TESTKEYS: #REF!
Name TESTVKEY: #REF!
Name TESTVKEY: #REF!

Sheet _com.sap.ip.bi.xl.hiddensheet

Sheet SUMMARY2
G1: 46143
E3: Values
B4: Material Group | C4: PH LV1 | D4: PH LV2 | E4: Total Stock value | F4: Avg COS, MC.5 | G4: T/O Days | H4: Total Provision | I4: % Prov/Stock | J4: Amount W/O age | K4: % W/O age | L4: Stk Val 01-03mo | M4: % 1-3mths | N4: Stk Val 04-06mo | O4: % 4-6mths | P4: Stk Val 07-12mo | Q4: %7-12mth | R4: Stk Val 13-24mo | S4: %13-24mth | T4: Stk Val 1Abv24mo | U4: %abv 24mth
B5: FG | C5: Mould | D5: Mould | E5: 1201517.2 | F5: 0 | G5: 0 | H5: 0 | I5: 0 | J5: 1201517.2 | K5: 1 | L5: 0 | M5: 0 | N5: 0 | O5: 0 | P5: 0 | Q5: 0 | R5: 0 | S5: 0 | T5: 0 | U5: 0
C6: PE | D6: Bottle | E6: 109804.8 | F6: 97209.593 | G6: 33.887026 | H6: 1767.3 | I6: 0.016094925 | J6: 0 | K6: 0 | L6: 105878.2 | M6: 0.96424018 | N6: 0 | O6: 0 | P6: 662.6 | Q6: 0.0060343446 | R6: 3264 | S6: 0.029725476 | T6: 0 | U6: 0
D7: Closure/Lid/ Handle | E7: 173440.27 | F7: 191471.05 | G7: 27.174908 | H7: 8532.82 | I7: 0.049197456 | J7: 0 | K7: 0 | L7: 145404.66 | M7: 0.83835582 | N7: 5188.27 | O7: 0.029913872 | P7: 12279.27 | Q7: 0.070798264 | R7: 10409.07 | S7: 0.060015301 | T7: 159 | U7: 0.00091674212
D8: Jerrycan | E8: 63397.89 | F8: 113402.88 | G8: 16.771503 | H8: 543.42 | I8: 0.0085715786 | J8: 0 | K8: 0 | L8: 62000.64 | M8: 0.97796062 | N8: 0 | O8: 0 | P8: 0 | Q8: 0 | R8: 1397.25 | S8: 0.022039377 | T8: 0 | U8: 0
C9: PET | D9: Bottle | E9: 495273.77 | F9: 597766.91 | G9: 24.856199 | H9: 7734.02 | I9: 0.015615646 | J9: 0 | K9: 0 | L9: 436947.22 | M9: 0.88223372 | N9: 36258.1 | O9: 0.073208198 | P9: 12365.04 | Q9: 0.024966071 | R9: 8704.03 | S9: 0.017574179 | T9: 999.38 | U9: 0.0020178335
D10: Jar /Container/Tub | E10: 220149.72 | F10: 259977.48 | G10: 25.404091 | H10: 6671.25 | I10: 0.030303241 | J10: 0 | K10: 0 | L10: 174298.82 | M10: 0.79172856 | N10: 16447.17 | O10: 0.074709021 | P10: 24410.53 | Q10: 0.11088149 | R10: 4828.2 | S10: 0.021931438 | T10: 165 | U10: 0.00074948994
C11: PP | D11: Bottle | E11: 228950.99 | F11: 447357.87 | G11: 15.353546 | H11: 0 | I11: 0 | J11: 145.8 | K11: 0.00063681751 | L11: 228613.92 | M11: 0.99852776 | N11: 191.27 | O11: 0.00083541897 | P11: 0 | Q11: 0 | R11: 0 | S11: 0 | T11: 0 | U11: 0
D12: Closure/Lid/ Handle | E12: 135062.22 | F12: 115924.66 | G12: 34.952587 | H12: 2077.32 | I12: 0.015380467 | J12: 0 | K12: 0 | L12: 115270.33 | M12: 0.85346095 | N12: 4105.19 | O12: 0.030394806 | P12: 15434.7 | Q12: 0.11427844 | R12: 252 | S12: 0.0018658067 | T12: 0 | U12: 0
D13: Jar /Container/Tub | E13: 61137.74 | F13: 47581.147 | G13: 38.547457 | H13: 203.42 | I13: 0.0033272411 | J13: 0 | K13: 0 | L13: 59745.92 | M13: 0.97723468 | N13: 171.42 | O13: 0.0028038328 | P13: 1220.4 | Q13: 0.019961484 | R13: 0 | S13: 0 | T13: 0 | U13: 0
C14: Secondary/ Component | D14: LABEL, IML, STICKER, SEALED ETC | E14: 275278.59 | F14: 191789.22 | G14: 43.059551 | H14: 22800.67 | I14: 0.082827618 | J14: 0 | K14: 0 | L14: 207155.44 | M14: 0.75253015 | N14: 22686.14 | O14: 0.082411567 | P14: 17957.42 | Q14: 0.065233624 | R14: 25291.84 | S14: 0.091877251 | T14: 2187.75 | U14: 0.0079474034
C15: Nylon | D15: Component | F15: 50 | G15: 0 | I15: 0 | K15: 0 | M15: 0 | O15: 0 | Q15: 0 | S15: 0 | U15: 0
B16: FG Total | E16: 2964013.2 | F16: 2062530.8 | G16: 43.112275 | H16: 50330.22 | I16: 0.01698043 | J16: 1201663 | K16: 0.40541756 | L16: 1535315.1 | M16: 0.51798526 | N16: 85047.56 | O16: 0.028693381 | P16: 84329.96 | Q16: 0.028451277 | R16: 54146.39 | S16: 0.018267931 | T16: 3511.13 | U16: 0.0011845865
B17: RM | C17: Additives | D17: Additives | E17: 206251.87 | F17: 40796.227 | G17: 151.66981 | H17: 15518.06 | I17: 0.075238397 | J17: 0 | K17: 0 | L17: 112711.66 | M17: 0.54647582 | N17: 52650.02 | O17: 0.25527051 | P17: 29448.63 | Q17: 0.14277994 | R17: 6323.39 | S17: 0.030658583 | T17: 5118.17 | U17: 0.024815145
C18: PE | D18: Virgin grade | E18: 1230752.2 | F18: 213273.78 | G18: 173.12285 | H18: 30684.37 | I18: 0.024931396 | J18: 0 | K18: 0 | L18: 1070678.5 | M18: 0.86993833 | N18: 90324.26 | O18: 0.073389477 | P18: 40780.96 | Q18: 0.033134989 | R18: 28876.06 | S18: 0.023462124 | T18: 92.4 | U18: 7.5076039e-05
D19: Internal Regrind | E19: 0 | F19: 0 | G19: 0 | H19: 0 | I19: 0 | J19: 0 | K19: 0 | L19: 0 | M19: 0 | N19: 0 | O19: 0 | P19: 0 | Q19: 0 | R19: 0 | S19: 0 | T19: 0 | U19: 0
C20: PET | D20: Preform | E20: 84309.07 | F20: 60804.273 | G20: 41.596946 | H20: 766.21 | I20: 0.0090881088 | J20: 0 | K20: 0 | L20: 68311.62 | M20: 0.81025233 | N20: 14743.75 | O20: 0.17487739 | P20: 0 | Q20: 0 | R20: 1253.7 | S20: 0.014870286 | T20: 0 | U20: 0
D21: Recycled | E21: 189098.44 | F21: 25894.43 | G21: 219.08006 | H21: 0 | I21: 0 | J21: 0 | K21: 0 | L21: 120147.51 | M21: 0.63537018 | N21: 68950.93 | O21: 0.36462982 | P21: 0 | Q21: 0 | R21: 0 | S21: 0 | T21: 0 | U21: 0
D22: Virgin grade | E22: 789122.67 | F22: 438114.65 | G22: 54.035353 | H22: 25781.12 | I22: 0.032670611 | J22: 0 | K22: 0 | L22: 729522.55 | M22: 0.92447293 | N22: 9240 | O22: 0.011709206 | P22: 0 | Q22: 0 | R22: 50360.12 | S22: 0.06381786 | T22: 0 | U22: 0
C23: PP | D23: Virgin grade | E23: 1137022.4 | F23: 311770.81 | G23: 109.40944 | H23: 3140.72 | I23: 0.0027622324 | J23: 0 | K23: 0 | L23: 1052630.6 | M23: 0.92577823 | N23: 72103.74 | O23: 0.063414531 | P23: 12208.89 | Q23: 0.010737599 | R23: 0 | S23: 0 | T23: 79.18 | U23: 6.9638032e-05
D24: Internal Regrind | E24: 0 | F24: 0 | G24: 0 | H24: 0 | I24: 0 | J24: 0 | K24: 0 | L24: 0 | M24: 0 | N24: 0 | O24: 0 | P24: 0 | Q24: 0 | R24: 0 | S24: 0 | T24: 0 | U24: 0
C25: Nylon | D25: Virgin grade | E25: 1574.52 | F25: 6.8233333 | G25: 6922.6575 | H25: 0 | I25: 0 | J25: 0 | K25: 0 | L25: 1450.01 | M25: 0.92092193 | N25: 124.51 | O25: 0.079078068 | P25: 0 | Q25: 0 | R25: 0 | S25: 0 | T25: 0 | U25: 0
B26: RM Total | E26: 3638131.1 | F26: 1090661 | G26: 100.07136 | H26: 75890.48 | I26: 0.020859743 | J26: 0 | K26: 0 | L26: 3155452.4 | M26: 0.86732784 | N26: 308137.21 | O26: 0.084696565 | P26: 82438.48 | Q26: 0.022659568 | R26: 86813.27 | S26: 0.023862051 | T26: 5289.75 | U26: 0.0014539745
B27: Grand Total | E27: 6602144.3 | F27: 3153191.8 | G27: 62.813918 | H27: 126220.7 | I27: 0.019118137 | J27: 1201663 | K27: 0.18201102 | L27: 4690767.6 | M27: 0.71049152 | N27: 393184.77 | O27: 0.059554101 | P27: 166768.44 | Q27: 0.025259739 | R27: 140959.66 | S27: 0.021350587 | T27: 8800.88 | U27: 0.0013330336

Sheet Ageing Sum
A1: Summary Stock Ageing
A3: Stock Type | B3: Ageing | C3: Jan | D3: Feb | E3: Mar | F3: Apr | G3: May | H3: Jun | I3: Jul | J3: Aug | K3: Sep | L3: Oct | M3: Nov | N3: Dec
A4: FG | B4: 4-6 months | C4: 86956.52 | D4: 92538.73 | E4: 57291.35 | F4: 59614.06 | G4: 85047.56
B5: 7-12 months | C5: 92003.46 | D5: 99289.73 | E5: 107022.88 | F5: 89652.01 | G5: 84329.96
B6: 13-24 months | C6: 32178.63 | D6: 32692.41 | E6: 40197.27 | F6: 47409.72 | G6: 54146.39
B7: > 24 months | C7: 2297.27 | D7: 458.67 | E7: 458.67 | F7: 724.77 | G7: 3511.13
B8: FG Total | C8: =SUM(C4:C7) -> 213435.88 | D8: =SUM(D4:D7) -> 224979.54 | E8: =SUM(E4:E7) -> 204970.17 | F8: =SUM(F4:F7) -> 197400.56 | G8: =SUM(G4:G7) -> 227035.04 | H8: =SUM(H4:H7) -> 0 | I8: =SUM(I4:I7) -> 0 | J8: =SUM(J4:J7) -> 0 | ... N8: =SUM(N4:N7) -> 0
A9: RM | B9: 4-6 months | C9: 113007.44 | D9: 59869.03 | E9: 52139.76 | F9: 74553.2 | G9: 308137.21
B10: 7-12 months | C10: 162412.62 | D10: 166354.16 | E10: 110348.93 | F10: 93375.28 | G10: 82438.48
B11: 13-24 months | C11: 25147.75 | D11: 29652.41 | E11: 102724.38 | F11: 104354.25 | G11: 86813.27
B12: > 24 months | C12: 4640.19 | D12: 4664.15 | E12: 4649.05 | F12: 4928.98 | G12: 5289.75
B13: RM Total | C13: =SUM(C9:C12) -> 305208 | D13: =SUM(D9:D12) -> 260539.75 | E13: =SUM(E9:E12) -> 269862.12 | F13: =SUM(F9:F12) -> 277211.71 | G13: =SUM(G9:G12) -> 482678.71 | H13: =SUM(H9:H12) -> 0 | I13: =SUM(I9:I12) -> 0 | J13: =SUM(J9:J12) -> 0 | ... N13: =SUM(N9:N12) -> 0

Sheet  Comparisons _working 
A1: MONTH | B1: PH LEVEL 1 | C1: PH LEVEL 2 | D1: Total Stock value | E1: Amount W/O age | F1: % W/O age | G1: Stk Val 01-03mo | H1: % 1-3mths | I1: Stk Val 04-06mo | J1: % 4-6mths | K1: Stk Val 07-12mo | L1: %7-12mth | M1: Stk Val 13-24mo | N1: %13-24mth | O1: Stk Val 1Abv24mo | P1: %abv 24mth | Q1: Total Provision | R1: Avg COS, MC.5 | S1: % Prov/Stock | T1: T/O Days | W1: PH LEVEL 1 | X1: Additives
A2: Jul'24 | B2: Additives | C2: Additives | D2: 198110.7 | E2: 0 | F2: 0 | G2: 141065.31 | H2: 0.71205296 | I2: 26844.25 | J2: 0.13550126 | K2: 7389.75 | L2: 0.037301115 | M2: 12191.15 | N2: 0.06153706 | O2: 10620.24 | P2: 0.053607604 | Q2: 18598.39 | R2: 38505.423 | S2: 0.093878776 | T2: 154.35023
A3: Jul'24 | B3: Mould | C3: Mould | D3: 348760 | E3: 348760 | F3: 1 | G3: 0 | H3: 0 | I3: 0 | J3: 0 | K3: 0 | L3: 0 | M3: 0 | N3: 0 | O3: 0 | P3: 0 | Q3: 0 | R3: 99515.603 | S3: 0 | T3: 105.13728 | Y3: Values
A4: Jul'24 | B4: PE | C4: Bottle | D4: 87501.44 | E4: 0 | F4: 0 | G4: 85124.98 | H4: 0.9728409 | I4: 441.1 | J4: 0.0050410599 | K4: 1935.36 | L4: 0.022118036 | M4: 0 | N4: 0 | O4: 0 | P4: 0 | Q4: 107.53 | R4: 116793.03 | S4: 0.0012288941 | T4: 22.476026 | W4: PH LEVEL 2 | X4: MONTH | Y4: Sum of Total Stock value | Z4: Sum of Stk Val 01-03mo | AA4: Sum of Stk Val 04-06mo | AB4: Sum of Stk Val 07-12mo | AC4: Sum of Stk Val 13-24mo | AD4: Sum of Stk Val 1Abv24mo | AE4: Sum of Total Provision | AF4: Sum of Avg COS, MC.5 | AG4: Sum of % Prov/Stock | AH4: Sum of T/O Days
A5: Jul'24 | B5: =B4 -> PE | C5: Closure/Lid/ Handle | D5: 199796.53 | E5: 0 | F5: 0 | G5: 188659.28 | H5: 0.94425704 | I5: 6568.97 | J5: 0.032878299 | K5: 3058.05 | L5: 0.015305821 | M5: 1033.23 | N5: 0.0051714111 | O5: 477 | P5: 0.0023874289 | Q5: 2011.21 | R5: 151537.09 | S5: 0.010066291 | T5: 39.553985 | W5: Additives | X5: Aug'24 | Y5: 174896.2 | Z5: 116445.33 | AA5: 27936.11 | AB5: 9349.93 | AC5: 9659.71 | AD5: 11505.13 | AE5: 18515.87 | AF5: 39199.557 | AG5: 0.10586777 | AH5: 133.85065
A6: Jul'24 | B6: =B5 -> PE | C6: Jerrycan | D6: 15020.64 | E6: 0 | F6: 0 | G6: 15020.64 | H6: 1 | I6: 0 | J6: 0 | K6: 0 | L6: 0 | M6: 0 | N6: 0 | O6: 0 | P6: 0 | Q6: 0 | R6: 4723.2 | S6: 0 | T6: 95.405488 | X6: Jul'24 | Y6: 198110.7 | Z6: 141065.31 | AA6: 26844.25 | AB6: 7389.75 | AC6: 12191.15 | AD6: 10620.24 | AE6: 18598.39 | AF6: 38505.423 | AG6: 0.093878776 | AH6: 154.35023
A7: Jul'24 | B7: =B6 -> PE | C7: Virgin grade | D7: 553555.01 | E7: 0 | F7: 0 | G7: 467691.23 | H7: 0.84488664 | I7: 56898.8 | J7: 0.10278798 | K7: 11330.5 | L7: 0.020468607 | M7: 14126.84 | N7: 0.02552021 | O7: 3507.64 | P7: 0.0063365699 | Q7: 11519.95 | R7: 139695.05 | S7: 0.020810849 | T7: 118.87788
A8: Jul'24 | B8: PET | C8: Bottle | D8: 513467.79 | E8: 0 | F8: 0 | G8: 479836.04 | H8: 0.93450076 | I8: 16175.02 | J8: 0.031501528 | K8: 102.03 | L8: 0.00019870769 | M8: 17232.6 | N8: 0.033561209 | O8: 122.1 | P8: 0.00023779486 | Q8: 12455.46 | R8: 685418.32 | S8: 0.024257529 | T8: 22.473916
A9: Jul'24 | B9: =B8 -> PET | C9: Jar /Container/Tub | D9: 325367.07 | E9: 0 | F9: 0 | G9: 249635.37 | H9: 0.76724227 | I9: 62527.02 | J9: 0.19217378 | K9: 10964.7 | L9: 0.033699477 | M9: 216.3 | N9: 0.00066478762 | O9: 2023.68 | P9: 0.0062196829 | Q9: 3219.16 | R9: 205978.26 | S9: 0.009893933 | T9: 47.388555
A10: Jul'24 | B10: =B9 -> PET | C10: Preform | D10: 35554.14 | E10: 0 | F10: 0 | G10: 35554.14 | H10: 1 | I10: 0 | J10: 0 | K10: 0 | L10: 0 | M10: 0 | N10: 0 | O10: 0 | P10: 0 | Q10: 0 | R10: 58072.403 | S10: 0 | T10: 18.367144 | W10: PH LEVEL 1 | X10: Mould
A11: Jul'24 | B11: =B10 -> PET | C11: Recycled | D11: 60085.87 | E11: 0 | F11: 0 | G11: 60085.87 | H11: 1 | I11: 0 | J11: 0 | K11: 0 | L11: 0 | M11: 0 | N11: 0 | O11: 0 | P11: 0 | Q11: 0 | R11: 20640.277 | S11: 0 | T11: 87.332943
A12: Jul'24 | B12: =B11 -> PET | C12: Virgin grade | D12: 750671.75 | E12: 0 | F12: 0 | G12: 740379.79 | H12: 0.98628967 | I12: 0 | J12: 0 | K12: 10291.95 | L12: 0.01371032 | M12: 0.01 | N12: 1.3321402e-08 | O12: 0 | P12: 0 | Q12: 1143.65 | R12: 474365.14 | S12: 0.0015235021 | T12: 47.474299 | Y12: Values
A13: Jul'24 | B13: PP | C13: Bottle | D13: 365184.62 | E13: 11241.9 | F13: 0.030784155 | G13: 348702.92 | H13: 0.95486749 | I13: 4131 | J13: 0.011312086 | K13: 1108.8 | L13: 0.0030362724 | M13: 0 | N13: 0 | O13: 0 | P13: 0 | Q13: 308.02 | R13: 445025.06 | S13: 0.00084346378 | T13: 24.617802 | W13: PH LEVEL 2 | X13: MONTH | Y13: Sum of Total Stock value | Z13: Sum of Stk Val 01-03mo | AA13: Sum of Stk Val 04-06mo | AB13: Sum of Stk Val 07-12mo | AC13: Sum of Stk Val 13-24mo | AD13: Sum of Stk Val 1Abv24mo | AE13: Sum of Total Provision | AF13: Sum of Avg COS, MC.5 | AG13: Sum of % Prov/Stock | AH13: Sum of T/O Days
A14: Jul'24 | B14: =B13 -> PP | C14: Closure/Lid/ Handle | D14: 184403.23 | E14: 0 | F14: 0 | G14: 159894.98 | H14: 0.86709425 | I14: 0 | J14: 0 | K14: 10739.87 | L14: 0.058241225 | M14: 8308.38 | N14: 0.045055501 | O14: 5460 | P14: 0.029609026 | Q14: 13072.62 | R14: 137963.63 | S14: 0.070891491 | T14: 40.098226 | W14: Mould | X14: Jul'24 | Y14: 348760 | Z14: 0 | AA14: 0 | AB14: 0 | AC14: 0 | AD14: 0 | AE14: 0 | AF14: 99515.603 | AG14: 0 | AH14: 105.13728
A15: Jul'24 | B15: =B14 -> PP | C15: Jar /Container/Tub | D15: 30733.09 | E15: 0 | F15: 0 | G15: 30733.09 | H15: 1 | I15: 0 | J15: 0 | K15: 0 | L15: 0 | M15: 0 | N15: 0 | O15: 0 | P15: 0 | Q15: 0 | R15: 47157.76 | S15: 0 | T15: 19.55124 | X15: Aug'24 | Y15: 380628.31 | Z15: 0 | AA15: 0 | AB15: 0 | AC15: 0 | AD15: 0 | AE15: 0 | AF15: 99515.603 | AG15: 0 | AH15: 114.74431
A16: Jul'24 | B16: =B15 -> PP | C16: Virgin grade | D16: 425606.81 | E16: 0 | F16: 0 | G16: 422176.14 | H16: 0.99193934 | I16: 1987.34 | J16: 0.0046694272 | K16: 0 | L16: 0 | M16: 103.99 | N16: 0.0002443335 | O16: 1339.33 | P16: 0.0031468716 | Q16: 1408.66 | R16: 373444.8 | S16: 0.0033097685 | T16: 34.190339
A17: Jul'24 | B17: Secondary/ Component | C17: LABEL, IML, STICKER, SEALED ETC | D17: 233438.85 | E17: 0 | F17: 0 | G17: 207493.26 | H17: 0.88885488 | I17: 13209.08 | J17: 0.056584754 | K17: 1116.75 | L17: 0.0047839081 | M17: 7499.14 | N17: 0.032124644 | O17: 4120.62 | P17: 0.017651818 | Q17: 7856.29 | R17: 175979.32 | S17: 0.033654595 | T17: 39.795389
A18: Jul'24 | B18: Supplies | C18: Logistic & Other Supplies | D18: 0 | E18: 0 | F18: 0 | G18: 0 | H18: 0 | I18: 0 | J18: 0 | K18: 0 | L18: 0 | M18: 0 | N18: 0 | O18: 0 | P18: 0 | Q18: 0 | R18: 0 | S18: 0 | T18: 0
A19: Aug'24 | B19: Additives | C19: Additives | D19: 174896.2 | E19: 0 | F19: 0 | G19: 116445.33 | H19: 0.6657968 | I19: 27936.11 | J19: 0.15972966 | K19: 9349.93 | L19: 0.053459881 | M19: 9659.71 | N19: 0.055231103 | O19: 11505.13 | P19: 0.065782618 | Q19: 18515.87 | R19: 39199.557 | S19: 0.10586777 | T19: 133.85065
A20: Aug'24 | B20: Mould | C20: Mould | D20: 380628.31 | E20: 380628.31 | F20: 1 | G20: 0 | H20: 0 | I20: 0 | J20: 0 | K20: 0 | L20: 0 | M20: 0 | N20: 0 | O20: 0 | P20: 0 | Q20: 0 | R20: 99515.603 | S20: 0 | T20: 114.74431 | W20: PH LEVEL 1 | X20: PE
A21: Aug'24 | B21: PE | C21: Bottle | D21: 150156.36 | E21: 0 | F21: 0 | G21: 148033.72 | H21: 0.9858638 | I21: 671.12 | J21: 0.0044694744 | K21: 1451.52 | L21: 0.0096667234 | M21: 0 | N21: 0 | O21: 0 | P21: 0 | Q21: 161.29 | R21: 122912.15 | S21: 0.001074147 | T21: 36.64968
A22: Aug'24 | B22: =B21 -> PE | C22: Closure/Lid/ Handle | D22: 287882.15 | E22: 0 | F22: 0 | G22: 274522.32 | H22: 0.95359271 | I22: 7380.93 | J22: 0.025638721 | K22: 4758.7 | L22: 0.016530028 | M22: 796.2 | N22: 0.0027657151 | O22: 424 | P22: 0.0014728249 | Q22: 2069.3 | R22: 139223.02 | S22: 0.0071880108 | T22: 62.03331 | Y22: Values
A23: Aug'24 | B23: =B22 -> PE | C23: Jerrycan | D23: 58181.76 | E23: 0 | F23: 0 | G23: 58181.76 | H23: 1 | I23: 0 | J23: 0 | K23: 0 | L23: 0 | M23: 0 | N23: 0 | O23: 0 | P23: 0 | Q23: 0 | R23: 7344 | S23: 0 | T23: 237.67059 | W23: PH LEVEL 2 | X23: MONTH | Y23: Sum of Total Stock value | Z23: Sum of Stk Val 01-03mo | AA23: Sum of Stk Val 04-06mo | AB23: Sum of Stk Val 07-12mo | AC23: Sum of Stk Val 13-24mo | AD23: Sum of Stk Val 1Abv24mo | AE23: Sum of Total Provision | AF23: Sum of Avg COS, MC.5 | AG23: Sum of % Prov/Stock | AH23: Sum of T/O Days
A24: Aug'24 | B24: =B23 -> PE | C24: Virgin grade | D24: 555388.21 | E24: 0 | F24: 0 | G24: 495663.07 | H24: 0.89246236 | I24: 31736.64 | J24: 0.057143165 | K24: 11857.7 | L24: 0.021350291 | M24: 12623.16 | N24: 0.022728534 | O24: 3507.64 | P24: 0.0063156544 | Q24: 12158.01 | R24: 156079.96 | S24: 0.021891012 | T24: 106.75071 | W24: Bottle | X24: Jul'24 | Y24: 87501.44 | Z24: 85124.98 | AA24: 441.1 | AB24: 1935.36 | AC24: 0 | AD24: 0 | AE24: 107.53 | AF24: 116793.03 | AG24: 0.0012288941 | AH24: 22.476026
A25: Aug'24 | B25: PET | C25: Bottle | D25: 645557.34 | E25: 0 | F25: 0 | G25: 611600.9 | H25: 0.94739981 | I25: 16372.71 | J25: 0.025362131 | K25: 229.03 | L25: 0.00035477871 | M25: 17232.6 | N25: 0.026694143 | O25: 122.1 | P25: 0.00018913889 | Q25: 13425.63 | R25: 683365.14 | S25: 0.02079696 | T25: 28.340223 | X25: Aug'24 | Y25: 150156.36 | Z25: 148033.72 | AA25: 671.12 | AB25: 1451.52 | AC25: 0 | AD25: 0 | AE25: 161.29 | AF25: 122912.15 | AG25: 0.001074147 | AH25: 36.64968
A26: Aug'24 | B26: =B25 -> PET | C26: Jar /Container/Tub | D26: 321946.26 | E26: 0 | F26: 0 | G26: 187806.45 | H26: 0.5833472 | I26: 122342.73 | J26: 0.38000979 | K26: 9557.1 | L26: 0.029685389 | M26: 216.3 | N26: 0.00067185126 | O26: 2023.68 | P26: 0.0062857696 | Q26: 3449.34 | R26: 204201.88 | S26: 0.010714024 | T26: 47.298231 | W26: Closure/Lid/ Handle | X26: Jul'24 | Y26: 199796.53 | Z26: 188659.28 | AA26: 6568.97 | AB26: 3058.05 | AC26: 1033.23 | AD26: 477 | AE26: 2011.21 | AF26: 151537.09 | AG26: 0.010066291 | AH26: 39.553985
A27: Aug'24 | B27: =B26 -> PET | C27: Preform | D27: 34724.7 | E27: 0 | F27: 0 | G27: 34724.7 | H27: 1 | I27: 0 | J27: 0 | K27: 0 | L27: 0 | M27: 0 | N27: 0 | O27: 0 | P27: 0 | Q27: 0 | R27: 57390.893 | S27: 0 | T27: 18.151678 | X27: Aug'24 | Y27: 287882.15 | Z27: 274522.32 | AA27: 7380.93 | AB27: 4758.7 | AC27: 796.2 | AD27: 424 | AE27: 2069.3 | AF27: 139223.02 | AG27: 0.0071880108 | AH27: 62.03331
A28: Aug'24 | B28: =B27 -> PET | C28: Recycled | D28: 39794.75 | E28: 0 | F28: 0 | G28: 39794.75 | H28: 1 | I28: 0 | J28: 0 | K28: 0 | L28: 0 | M28: 0 | N28: 0 | O28: 0 | P28: 0 | Q28: 0 | R28: 20967.773 | S28: 0 | T28: 56.937019 | W28: Jerrycan | X28: Jul'24 | Y28: 15020.64 | Z28: 15020.64 | AA28: 0 | AB28: 0 | AC28: 0 | AD28: 0 | AE28: 0 | AF28: 4723.2 | AG28: 0 | AH28: 95.405488
A29: Aug'24 | B29: =B28 -> PET | C29: Virgin grade | D29: 741415.45 | E29: 0 | F29: 0 | G29: 731033.02 | H29: 0.98599647 | I29: 0 | J29: 0 | K29: 10382.42 | L29: 0.014003512 | M29: 0.01 | N29: 1.3487715e-08 | O29: 0 | P29: 0 | Q29: 1730.55 | R29: 492597.21 | S29: 0.0023341165 | T29: 45.15345 | X29: Aug'24 | Y29: 58181.76 | Z29: 58181.76 | AA29: 0 | AB29: 0 | AC29: 0 | AD29: 0 | AE29: 0 | AF29: 7344 | AG29: 0 | AH29: 237.67059
A30: Aug'24 | B30: PP | C30: Bottle | D30: 366226.82 | E30: 153.9 | F30: 0.00042023137 | G30: 360833.12 | H30: 0.98527224 | I30: 0 | J30: 0 | K30: 5239.8 | L30: 0.014307527 | M30: 0 | N30: 0 | O30: 0 | P30: 0 | Q30: 599.15 | R30: 486580.35 | S30: 0.001636008 | T30: 22.579631 | W30: Virgin grade | X30: Jul'24 | Y30: 553555.01 | Z30: 467691.23 | AA30: 56898.8 | AB30: 11330.5 | AC30: 14126.84 | AD30: 3507.64 | AE30: 11519.95 | AF30: 139695.05 | AG30: 0.020810849 | AH30: 118.87788
A31: Aug'24 | B31: =B30 -> PP | C31: Closure/Lid/ Handle | D31: 161880.85 | E31: 0 | F31: 0 | G31: 138986.84 | H31: 0.85857493 | I31: 482.52 | J31: 0.0029807108 | K31: 8643.11 | L31: 0.0533918 | M31: 5675.1 | N31: 0.035057266 | O31: 8093.28 | P31: 0.04999529 | Q31: 13635.15 | R31: 138883.49 | S31: 0.084229543 | T31: 34.967622 | X31: Aug'24 | Y31: 555388.21 | Z31: 495663.07 | AA31: 31736.64 | AB31: 11857.7 | AC31: 12623.16 | AD31: 3507.64 | AE31: 12158.01 | AF31: 156079.96 | AG31: 0.021891012 | AH31: 106.75071
A32: Aug'24 | B32: =B31 -> PP | C32: Jar /Container/Tub | D32: 33477.68 | E32: 0 | F32: 0 | G32: 33477.68 | H32: 1 | I32: 0 | J32: 0 | K32: 0 | L32: 0 | M32: 0 | N32: 0 | O32: 0 | P32: 0 | Q32: 0 | R32: 37667.923 | S32: 0 | T32: 26.662749
A33: Aug'24 | B33: =B32 -> PP | C33: Virgin grade | D33: 435459.66 | E33: 0 | F33: 0 | G33: 434016.74 | H33: 0.99668644 | I33: 0 | J33: 0 | K33: 0 | L33: 0 | M33: 103.59 | N33: 0.00023788656 | O33: 1339.34 | P33: 0.0030756925 | Q33: 1414.16 | R33: 369047.03 | S33: 0.0032475109 | T33: 35.398712
A34: Aug'24 | B34: Secondary/ Component | C34: LABEL, IML, STICKER, SEALED ETC | D34: 271897.34 | E34: 0 | F34: 0 | G34: 239643.75 | H34: 0.88137585 | I34: 13312.65 | J34: 0.048962046 | K34: 7469.44 | L34: 0.027471545 | M34: 7350.88 | N34: 0.027035498 | O34: 4120.62 | P34: 0.015155058 | Q34: 8594.59 | R34: 162216.95 | S34: 0.031609688 | T34: 50.284019
A35: Aug'24 | B35: Supplies | C35: Logistic & Other Supplies | D35: 0 | E35: 0 | F35: 0 | G35: 0 | H35: 0 | I35: 0 | J35: 0 | K35: 0 | L35: 0 | M35: 0 | N35: 0 | O35: 0 | P35: 0 | Q35: 0 | R35: 0 | S35: 0 | T35: 0
W37: PH LEVEL 1 | X37: PET
Y39: Values
W40: PH LEVEL 2 | X40: MONTH | Y40: Sum of Total Stock value | Z40: Sum of Stk Val 01-03mo | AA40: Sum of Stk Val 04-06mo | AB40: Sum of Stk Val 07-12mo | AC40: Sum of Stk Val 13-24mo | AD40: Sum of Stk Val 1Abv24mo | AE40: Sum of Total Provision | AF40: Sum of Avg COS, MC.5 | AG40: Sum of % Prov/Stock | AH40: Sum of T/O Days
W41: Bottle | X41: Jul'24 | Y41: 513467.79 | Z41: 479836.04 | AA41: 16175.02 | AB41: 102.03 | AC41: 17232.6 | AD41: 122.1 | AE41: 12455.46 | AF41: 685418.32 | AG41: 0.024257529 | AH41: 22.473916
X42: Aug'24 | Y42: 645557.34 | Z42: 611600.9 | AA42: 16372.71 | AB42: 229.03 | AC42: 17232.6 | AD42: 122.1 | AE42: 13425.63 | AF42: 683365.14 | AG42: 0.02079696 | AH42: 28.340223
...

Sheet working pv
C1: Values
A2: PH LEVEL 1 | B2: PH LEVEL 2 | C2: Total Stock value | D2: Amount W/O age | E2: % W/O age | F2: Stk Val 01-03mo | G2: % 1-3mths | H2: Stk Val 04-06mo | I2: % 4-6mths | J2: Stk Val 07-12mo | K2: %7-12mth | L2: Stk Val 13-24mo | M2: %13-24mth | N2: Stk Val 1Abv24mo | O2: %abv 24mth | P2: Total Provision | Q2: Avg COS, MC.5 | R2: % Prov/Stock | S2: T/O Days
A3: Additives | B3: Additives | C3: 174896.2 | D3: 0 | E3: 0 | F3: 116445.33 | G3: 0.6657968 | H3: 27936.11 | I3: 0.15972966 | J3: 9349.93 | K3: 0.053459881 | L3: 9659.71 | M3: 0.055231103 | N3: 11505.13 | O3: 0.065782618 | P3: 18515.87 | Q3: 39199.557 | R3: 0.10586777 | S3: 133.85065
A4: Mould | B4: Mould | C4: 380628.31 | D4: 380628.31 | E4: 1 | F4: 0 | G4: 0 | H4: 0 | I4: 0 | J4: 0 | K4: 0 | L4: 0 | M4: 0 | N4: 0 | O4: 0 | P4: 0 | Q4: 99515.603 | R4: 0 | S4: 114.74431
A5: PE | B5: Bottle | C5: 150156.36 | D5: 0 | E5: 0 | F5: 148033.72 | G5: 0.9858638 | H5: 671.12 | I5: 0.0044694744 | J5: 1451.52 | K5: 0.0096667234 | L5: 0 | M5: 0 | N5: 0 | O5: 0 | P5: 161.29 | Q5: 122912.15 | R5: 0.001074147 | S5: 36.64968
B6: Closure/Lid/ Handle | C6: 287882.15 | D6: 0 | E6: 0 | F6: 274522.32 | G6: 0.95359271 | H6: 7380.93 | I6: 0.025638721 | J6: 4758.7 | K6: 0.016530028 | L6: 796.2 | M6: 0.0027657151 | N6: 424 | O6: 0.0014728249 | P6: 2069.3 | Q6: 139223.02 | R6: 0.0071880108 | S6: 62.03331
B7: Jerrycan | C7: 58181.76 | D7: 0 | E7: 0 | F7: 58181.76 | G7: 1 | H7: 0 | I7: 0 | J7: 0 | K7: 0 | L7: 0 | M7: 0 | N7: 0 | O7: 0 | P7: 0 | Q7: 7344 | R7: 0 | S7: 237.67059
B8: Virgin grade | C8: 555388.21 | D8: 0 | E8: 0 | F8: 495663.07 | G8: 0.89246236 | H8: 31736.64 | I8: 0.057143165 | J8: 11857.7 | K8: 0.021350291 | L8: 12623.16 | M8: 0.022728534 | N8: 3507.64 | O8: 0.0063156544 | P8: 12158.01 | Q8: 156079.96 | R8: 0.021891012 | S8: 106.75071
A9: PET | B9: Bottle | C9: 645557.34 | D9: 0 | E9: 0 | F9: 611600.9 | G9: 0.94739981 | H9: 16372.71 | I9: 0.025362131 | J9: 229.03 | K9: 0.00035477871 | L9: 17232.6 | M9: 0.026694143 | N9: 122.1 | O9: 0.00018913889 | P9: 13425.63 | Q9: 683365.14 | R9: 0.02079696 | S9: 28.340223
B10: Jar /Container/Tub | C10: 321946.26 | D10: 0 | E10: 0 | F10: 187806.45 | G10: 0.5833472 | H10: 122342.73 | I10: 0.38000979 | J10: 9557.1 | K10: 0.029685389 | L10: 216.3 | M10: 0.00067185126 | N10: 2023.68 | O10: 0.0062857696 | P10: 3449.34 | Q10: 204201.88 | R10: 0.010714024 | S10: 47.298231
B11: Preform | C11: 34724.7 | D11: 0 | E11: 0 | F11: 34724.7 | G11: 1 | H11: 0 | I11: 0 | J11: 0 | K11: 0 | L11: 0 | M11: 0 | N11: 0 | O11: 0 | P11: 0 | Q11: 57390.893 | R11: 0 | S11: 18.151678
B12: Recycled | C12: 39794.75 | D12: 0 | E12: 0 | F12: 39794.75 | G12: 1 | H12: 0 | I12: 0 | J12: 0 | K12: 0 | L12: 0 | M12: 0 | N12: 0 | O12: 0 | P12: 0 | Q12: 20967.773 | R12: 0 | S12: 56.937019
B13: Virgin grade | C13: 741415.45 | D13: 0 | E13: 0 | F13: 731033.02 | G13: 0.98599647 | H13: 0 | I13: 0 | J13: 10382.42 | K13: 0.014003512 | L13: 0.01 | M13: 1.3487715e-08 | N13: 0 | O13: 0 | P13: 1730.55 | Q13: 492597.21 | R13: 0.0023341165 | S13: 45.15345
A14: PP | B14: Bottle | C14: 366226.82 | D14: 153.9 | E14: 0.00042023137 | F14: 360833.12 | G14: 0.98527224 | H14: 0 | I14: 0 | J14: 5239.8 | K14: 0.014307527 | L14: 0 | M14: 0 | N14: 0 | O14: 0 | P14: 599.15 | Q14: 486580.35 | R14: 0.001636008 | S14: 22.579631
B15: Closure/Lid/ Handle | C15: 161880.85 | D15: 0 | E15: 0 | F15: 138986.84 | G15: 0.85857493 | H15: 482.52 | I15: 0.0029807108 | J15: 8643.11 | K15: 0.0533918 | L15: 5675.1 | M15: 0.035057266 | N15: 8093.28 | O15: 0.04999529 | P15: 13635.15 | Q15: 138883.49 | R15: 0.084229543 | S15: 34.967622
B16: Jar /Container/Tub | C16: 33477.68 | D16: 0 | E16: 0 | F16: 33477.68 | G16: 1 | H16: 0 | I16: 0 | J16: 0 | K16: 0 | L16: 0 | M16: 0 | N16: 0 | O16: 0 | P16: 0 | Q16: 37667.923 | R16: 0 | S16: 26.662749
B17: Virgin grade | C17: 435459.66 | D17: 0 | E17: 0 | F17: 434016.74 | G17: 0.99668644 | H17: 0 | I17: 0 | J17: 0 | K17: 0 | L17: 103.59 | M17: 0.00023788656 | N17: 1339.34 | O17: 0.0030756925 | P17: 1414.16 | Q17: 369047.03 | R17: 0.0032475109 | S17: 35.398712
A18: Secondary/ Component | B18: LABEL, IML, STICKER, SEALED ETC | C18: 271897.34 | D18: 0 | E18: 0 | F18: 239643.75 | G18: 0.88137585 | H18: 13312.65 | I18: 0.048962046 | J18: 7469.44 | K18: 0.027471545 | L18: 7350.88 | M18: 0.027035498 | N18: 4120.62 | O18: 0.015155058 | P18: 8594.59 | Q18: 162216.95 | R18: 0.031609688 | S18: 50.284019
A19: Supplies | B19: Logistic & Other Supplies | C19: 0 | D19: 0 | E19: 0 | F19: 0 | G19: 0 | H19: 0 | I19: 0 | J19: 0 | K19: 0 | L19: 0 | M19: 0 | N19: 0 | O19: 0 | P19: 0 | Q19: 0 | R19: 0 | S19: 0
A20: (blank) | B20: (blank) | C20: 4659513.8 | D20: 380782.21 | E20: 0.081721446 | F20: 3904764.1 | G20: 0.83801965 | H20: 220235.41 | I20: 0.047265749 | J20: 68938.75 | K20: 0.014795267 | L20: 53657.55 | M20: 0.011515697 | N20: 31135.79 | O20: 0.0066821971 | P20: 75753.04 | R20: 0.016257713 | S20: 0
A21: Grand Total | C21: 9319027.7 | D21: 761564.42 | E21: 0.081721446 | F21: 7809528.3 | G21: 0.83801965 | H21: 440470.82 | I21: 0.047265749 | J21: 137877.5 | K21: 0.014795267 | L21: 107315.1 | M21: 0.011515697 | N21: 62271.58 | O21: 0.0066821971 | P21: 151506.08 | Q21: 3217192.9 | R21: 0.016257713 | S21: 86.898994

Sheet  Comparisons w Prior mth
A1: Stock Movement for AUG 2024
A4: Additives
A5: PH summary | B5: Month | C5: Sum of Total Stock value | D5: Sum of Stk Val 01-03mo | E5: Sum of Stk Val 04-06mo | F5: Sum of Stk Val 07-12mo | G5: Sum of Stk Val 13-24mo | H5: Sum of Stk Val 1Abv24mo | I5: Sum of Total Provision | J5: Sum of Avg COS, MC.5 | K5: Sum of % Prov/Stock | L5: Sum of T/O Days
A7: Additives | B7: Aug'24 | C7: 174896.2 | D7: 116445.33 | E7: 27936.11 | F7: 9349.93 | G7: 9659.71 | H7: 11505.13 | I7: 18515.87 | J7: 39199.557 | K7: 0.10586777 | L7: 133.85065
A8: =A7 -> Additives | B8: Jul'24 | C8: 198110.7 | D8: 141065.31 | E8: 26844.25 | F8: 7389.75 | G8: 12191.15 | H8: 10620.24 | I8: 18598.39 | J8: 38505.423 | K8: 0.093878776 | L8: 154.35023
A9: Increase/Decrease | C9: =C7-C8 -> -23214.5 | D9: =D7-D8 -> -24619.98 | E9: =E7-E8 -> 1091.86 | F9: =F7-F8 -> 1960.18 | G9: =G7-G8 -> -2531.44 | H9: =H7-H8 -> 884.89 | I9: =I7-I8 -> -82.52 | J9: =J7-J8 -> 694.13333
A13: Mould
A14: PH summary | B14: Month | C14: Sum of Total Stock value | D14: Sum of Stk Val 01-03mo | E14: Sum of Stk Val 04-06mo | F14: Sum of Stk Val 07-12mo | G14: Sum of Stk Val 13-24mo | H14: Sum of Stk Val 1Abv24mo | I14: Sum of Total Provision | J14: Sum of Avg COS, MC.5 | K14: Sum of % Prov/Stock | L14: Sum of T/O Days
A16: Mould | B16: Aug'24 | C16: 380628.31 | D16: 0 | E16: 0 | F16: 0 | G16: 0 | H16: 0 | I16: 0 | J16: 99515.603 | K16: 0 | L16: 114.74431
A17: =A16 -> Mould | B17: Jul'24 | C17: 348760 | D17: 0 | E17: 0 | F17: 0 | G17: 0 | H17: 0 | I17: 0 | J17: 99515.603 | K17: 0 | L17: 105.13728
A18: Increase/Decrease | C18: =C16-C17 -> 31868.31 | D18: =D16-D17 -> 0 | E18: =E16-E17 -> 0 | F18: =F16-F17 -> 0 | G18: =G16-G17 -> 0 | H18: =H16-H17 -> 0 | I18: =I16-I17 -> 0 | J18: =J16-J17 -> 0
A22: PE
A23: PH summary | B23: Month | C23: Sum of Total Stock value | D23: Sum of Stk Val 01-03mo | E23: Sum of Stk Val 04-06mo | F23: Sum of Stk Val 07-12mo | G23: Sum of Stk Val 13-24mo | H23: Sum of Stk Val 1Abv24mo | I23: Sum of Total Provision | J23: Sum of Avg COS, MC.5 | K23: Sum of % Prov/Stock | L23: Sum of T/O Days
A25: Bottle | B25: Aug'24 | C25: 150156.36 | D25: 148033.72 | E25: 671.12 | F25: 1451.52 | G25: 0 | H25: 0 | I25: 161.29 | J25: 122912.15 | K25: 0.001074147 | L25: 36.64968
A26: =A25 -> Bottle | B26: Jul'24 | C26: 87501.44 | D26: 85124.98 | E26: 441.1 | F26: 1935.36 | G26: 0 | H26: 0 | I26: 107.53 | J26: 116793.03 | K26: 0.0012288941 | L26: 22.476026
A27: Increase/Decrease | C27: =C25-C26 -> 62654.92 | D27: =D25-D26 -> 62908.74 | E27: =E25-E26 -> 230.02 | F27: =F25-F26 -> -483.84 | G27: =G25-G26 -> 0 | H27: =H25-H26 -> 0 | I27: =I25-I26 -> 53.76 | J27: =J25-J26 -> 6119.1133
A29: Closure/Lid/ Handle | B29: Aug'24 | C29: 287882.15 | D29: 274522.32 | E29: 7380.93 | F29: 4758.7 | G29: 796.2 | H29: 424 | I29: 2069.3 | J29: 139223.02 | K29: 0.0071880108 | L29: 62.03331
A30: =A29 -> Closure/Lid/ Handle | B30: Jul'24 | C30: 199796.53 | D30: 188659.28 | E30: 6568.97 | F30: 3058.05 | G30: 1033.23 | H30: 477 | I30: 2011.21 | J30: 151537.09 | K30: 0.010066291 | L30: 39.553985
A31: Increase/Decrease | C31: =C29-C30 -> 88085.62 | D31: =D29-D30 -> 85863.04 | E31: =E29-E30 -> 811.96 | F31: =F29-F30 -> 1700.65 | G31: =G29-G30 -> -237.03 | H31: =H29-H30 -> -53 | I31: =I29-I30 -> 58.09 | J31: =J29-J30 -> -12314.077
A33: Jerrycan | B33: Aug'24 | C33: 58181.76 | D33: 58181.76 | E33: 0 | F33: 0 | G33: 0 | H33: 0 | I33: 0 | J33: 7344 | K33: 0 | L33: 237.67059
A34: =A33 -> Jerrycan | B34: Jul'24 | C34: 15020.64 | D34: 15020.64 | E34: 0 | F34: 0 | G34: 0 | H34: 0 | I34: 0 | J34: 4723.2 | K34: 0 | L34: 95.405488
A35: Increase/Decrease | C35: =C33-C34 -> 43161.12 | D35: =D33-D34 -> 43161.12 | E35: =E33-E34 -> 0 | F35: =F33-F34 -> 0 | G35: =G33-G34 -> 0 | H35: =H33-H34 -> 0 | I35: =I33-I34 -> 0 | J35: =J33-J34 -> 2620.8
A37: Virgin grade | B37: Aug'24 | C37: 555388.21 | D37: 495663.07 | E37: 31736.64 | F37: 11857.7 | G37: 12623.16 | H37: 3507.64 | I37: 12158.01 | J37: 156079.96 | K37: 0.021891012 | L37: 106.75071
A38: =A37 -> Virgin grade | B38: Jul'24 | C38: 553555.01 | D38: 467691.23 | E38: 56898.8 | F38: 11330.5 | G38: 14126.84 | H38: 3507.64 | I38: 11519.95 | J38: 139695.05 | K38: 0.020810849 | L38: 118.87788
A39: Increase/Decrease | C39: =C37-C38 -> 1833.2 | D39: =D37-D38 -> 27971.84 | E39: =E37-E38 -> -25162.16 | F39: =F37-F38 -> 527.2 | G39: =G37-G38 -> -1503.68 | H39: =H37-H38 -> 0 | I39: =I37-I38 -> 638.06 | J39: =J37-J38 -> 16384.913
A43: PET
A44: PH summary | B44: Month | C44: Sum of Total Stock value | D44: Sum of Stk Val 01-03mo | E44: Sum of Stk Val 04-06mo | F44: Sum of Stk Val 07-12mo | G44: Sum of Stk Val 13-24mo | H44: Sum of Stk Val 1Abv24mo | I44: Sum of Total Provision | J44: Sum of Avg COS, MC.5 | K44: Sum of % Prov/Stock | L44: Sum of T/O Days
A46: Bottle | B46: Aug'24 | C46: 366226.82 | D46: 360833.12 | E46: 0 | F46: 5239.8 | G46: 0 | H46: 0 | I46: 599.15 | J46: 486580.35 | K46: 0.001636008 | L46: 22.579631
A47: =A46 -> Bottle | B47: Jul'24 | C47: 365184.62 | D47: 348702.92 | E47: 4131 | F47: 1108.8 | G47: 0 | H47: 0 | I47: 308.02 | J47: 445025.06 | K47: 0.00084346378 | L47: 24.617802
A48: Increase/Decrease | C48: =C46-C47 -> 1042.2 | D48: =D46-D47 -> 12130.2 | E48: =E46-E47 -> -4131 | F48: =F46-F47 -> 4131 | G48: =G46-G47 -> 0 | H48: =H46-H47 -> 0 | I48: =I46-I47 -> 291.13 | J48: =J46-J47 -> 41555.293
A50: Closure/Lid/ Handle | B50: Aug'24 | C50: 161880.85 | D50: 138986.84 | E50: 482.52 | F50: 8643.11 | G50: 5675.1 | H50: 8093.28 | I50: 13635.15 | J50: 138883.49 | K50: 0.084229543 | L50: 34.967622
A51: =A50 -> Closure/Lid/ Handle | B51: Jul'24 | C51: 184403.23 | D51: 159894.98 | E51: 0 | F51: 10739.87 | G51: 8308.38 | H51: 5460 | I51: 13072.62 | J51: 137963.63 | K51: 0.070891491 | L51: 40.098226
A52: Increase/Decrease | C52: =C50-C51 -> -22522.38 | D52: =D50-D51 -> -20908.14 | E52: =E50-E51 -> 482.52 | F52: =F50-F51 -> -2096.76 | G52: =G50-G51 -> -2633.28 | H52: =H50-H51 -> 2633.28 | I52: =I50-I51 -> 562.53 | J52: =J50-J51 -> 919.86
A54: Jar /Container/Tub | B54: Aug'24 | C54: 33477.68 | D54: 33477.68 | E54: 0 | F54: 0 | G54: 0 | H54: 0 | I54: 0 | J54: 37667.923 | K54: 0 | L54: 26.662749
A55: =A54 -> Jar /Container/Tub | B55: Jul'24 | C55: 30733.09 | D55: 30733.09 | E55: 0 | F55: 0 | G55: 0 | H55: 0 | I55: 0 | J55: 47157.76 | K55: 0 | L55: 19.55124
A56: Increase/Decrease | C56: =C54-C55 -> 2744.59 | D56: =D54-D55 -> 2744.59 | E56: =E54-E55 -> 0 | F56: =F54-F55 -> 0 | G56: =G54-G55 -> 0 | H56: =H54-H55 -> 0 | I56: =I54-I55 -> 0 | J56: =J54-J55 -> -9489.8367
A58: Virgin grade | B58: Aug'24 | C58: 435459.66 | D58: 434016.74 | E58: 0 | F58: 0 | G58: 103.59 | H58: 1339.34 | I58: 1414.16 | J58: 369047.03 | K58: 0.0032475109 | L58: 35.398712
A59: =A58 -> Virgin grade | B59: Jul'24 | C59: 425606.81 | D59: 422176.14 | E59: 1987.34 | F59: 0 | G59: 103.99 | H59: 1339.33 | I59: 1408.66 | J59: 373444.8 | K59: 0.0033097685 | L59: 34.190339
A60: Increase/Decrease | C60: =C58-C59 -> 9852.85 | D60: =D58-D59 -> 11840.6 | E60: =E58-E59 -> -1987.34 | F60: =F58-F59 -> 0 | G60: =G58-G59 -> -0.4 | H60: =H58-H59 -> 0.01 | I60: =I58-I59 -> 5.5 | J60: =J58-J59 -> -4397.7667
A64: Secondary/ Component
...

Sheet summary
C2: Values
A3: PH LV1 | B3: PH LV2 | C3: Sum of Tot Stock value | D3: Sum of Total Provision | E3: Sum of Total weight (kg) in KIR report
A4: Additives | B4: Additives | C4: 206251.87 | D4: 15518.06 | E4: 5230.36
A5: Mould | B5: Mould | C5: 1201517.2 | D5: 0 | E5: 0
A6: PE | B6: Bottle | C6: 109804.8 | D6: 1767.3 | E6: 10477.452
B7: Closure/Lid/ Handle | C7: 173440.27 | D7: 8532.82 | E7: 9500.7508
B8: Jerrycan | C8: 63397.89 | D8: 543.42 | E8: 14565.96
B9: Virgin grade | C9: 1230752.2 | D9: 30684.37 | E9: 165389.14
B10: Internal Regrind | C10: 0 | D10: 0 | E10: 10715
A11: PET | B11: Bottle | C11: 495273.77 | D11: 7734.02 | E11: 59084.199
B12: Jar /Container/Tub | C12: 220149.72 | D12: 6671.25 | E12: 25018.292
B13: Preform | C13: 84309.07 | D13: 766.21 | E13: 11862.048
B14: Recycled | C14: 189098.44 | D14: 0 | E14: 33051.599
B15: Virgin grade | C15: 789122.67 | D15: 25781.12 | E15: 164438.48
A16: PP | B16: Bottle | C16: 228950.99 | D16: 0 | E16: 19632.518
B17: Closure/Lid/ Handle | C17: 135062.22 | D17: 2077.32 | E17: 7562.3043
B18: Jar /Container/Tub | C18: 61137.74 | D18: 203.42 | E18: 6552.4
B19: Virgin grade | C19: 1137022.4 | D19: 3140.72 | E19: 147355.65
B20: Internal Regrind | C20: 0 | D20: 0 | E20: 1829
A21: Supplies | B21: Logistic & Other Supplies | C21: 0 | D21: 0 | E21: 0
A22: Secondary/ Component | B22: LABEL, IML, STICKER, SEALED ETC | C22: 275278.59 | D22: 22800.67 | E22: 0
A23: Nylon | B23: Virgin grade | C23: 1574.52 | D23: 0 | E23: 108.587
B24: Component | E24: 0
A25: Grand Total | C25: 6602144.3 | D25: 126220.7 | E25: 692373.75

Sheet details
A1: Data Source Name | B1: Stock Turn Over Days
A2: Cal Yr/Mon for Cost of Sls | C2: As at 31 MAY 2026
A3: JJPM SG BULOH | AE3: vlookup fr AO sale | AF3: vlookup fr MC.5 | AG3: COS - either column "AE" or "AF"
A5: Material Group | B5: MG1 | C5: Material | D5: Material Description | E5: Net weight | F5: PH Level1 | G5: PH Level2 | H5: PH Level3 | I5: ProdHier | J5: ProdHierachy | K5: Age Bucket 01 - 03 m | L5: Stk Val 01-03mo | M5: Age Bucket 04 - 06 m | N5: Stk Val 04-06mo | O5: Age Bucket 07 - 12 m | P5: Stk Val 07-12mo | Q5: Age Bucket 13 - 24 m | R5: Stk Val 13-24mo | S5: Age Bucket Abv 24 m | T5: Stk Val 1Abv24mo | U5: Stocks w/o Age Quantity | V5: Amount W/O age | W5: Batch Quantity | X5: Tot Stock value | Y5: Total Provision | Z5: Cost in LC | AA5: Avg Cost of sales | AB5: Stock Turn Over days | AC5: Total weight (kg) in KIR report | AD5: Extract fr Col C | AE5: COS fr AO Sales | AF5: COS fr MC.5 | AG5: Avg COS, MC.5 | AH5: PH LV1 | AI5: PH LV2
A6: Material Group | C6: Material | E6: Net weight | F6: PH Level1 | G6: PH Level2 | H6: PH Level3 | I6: ProdHier | L6: MYR | N6: MYR | P6: MYR | R6: MYR | T6: MYR | V6: MYR | X6: MYR | Y6: MYR | Z6: MYR | AA6: MYR | AD6: Net W | AF6: COS fr MC.5
A7: FG | B7: FG | C7: 322382 | D7: BC28-0060-M-R-CL-LW | E7: 11.300 G | F7: 60104 | G7: 601041000B | H7: 601041000B90000000 | I7: 601041000B90000000 | J7: Others | Z7: 1242 | AA7: 414 | AC7: =(AD7*W7)/1000 -> 0 | AD7: =LEFT(details!E7,5) -> 11.30 | AE7: =AA7 -> 414 | AF7: =VLOOKUP(C7,MC.5!B:P,15,FALSE)/3 -> 414 | AG7: =AE7 -> 414 | AH7: =VLOOKUP(F7,REF!B:C,2,FALSE) -> PET | AI7: =VLOOKUP(G7,REF!E:F,2,FALSE) -> Bottle
A8: FG | B8: FG | C8: 322383 | D8: BB38-0060-R-R-CL | E8: 12.500 G | F8: 60104 | G8: 601041000B | H8: 601041000B90000000 | I8: 601041000B90000000 | J8: Others | K8: 39600 | L8: 5940 | M8: 0 | N8: 0 | O8: 0 | P8: 0 | Q8: 0 | R8: 0 | S8: 0 | T8: 0 | U8: 0 | V8: 0 | W8: 39600 | X8: 5940 | Y8: 0 | Z8: 9570 | AA8: 3190 | AB8: 55.862069 | AC8: =(AD8*W8)/1000 -> 495 | AD8: =LEFT(details!E8,5) -> 12.50 | AE8: =AA8 -> 3190 | AF8: =VLOOKUP(C8,MC.5!B:P,15,FALSE)/3 -> 3190 | AG8: =AE8 -> 3190 | AH8: =VLOOKUP(F8,REF!B:C,2,FALSE) -> PET | AI8: =VLOOKUP(G8,REF!E:F,2,FALSE) -> Bottle
A9: FG | B9: FG | C9: 322389 | D9: BB38-0090-R-R-CL | E9: 12.500 G | F9: 60104 | G9: 601041000B | H9: 601041000B90000000 | I9: 601041000B90000000 | J9: Others | K9: 56160 | L9: 8424 | M9: 3900 | N9: 585 | O9: 0 | P9: 0 | Q9: 0 | R9: 0 | S9: 0 | T9: 0 | U9: 0 | V9: 0 | W9: 60060 | X9: 9009 | Y9: 0 | Z9: 7675.2 | AA9: 2558.4 | AB9: 105.64024 | AC9: =(AD9*W9)/1000 -> 750.75 | AD9: =LEFT(details!E9,5) -> 12.50 | AE9: =AA9 -> 2558.4 | AF9: =VLOOKUP(C9,MC.5!B:P,15,FALSE)/3 -> 2558.4 | AG9: =AE9 -> 2558.4 | AH9: =VLOOKUP(F9,REF!B:C,2,FALSE) -> PET | AI9: =VLOOKUP(G9,REF!E:F,2,FALSE) -> Bottle
A10: FG | B10: FG | C10: 322391 | D10: BX38-0100-BM-R-AM | E10: 20.000 G | F10: 60104 | G10: 601041000B | H10: 601041000B90000000 | I10: 601041000B90000000 | J10: Others | Z10: 1300 | AA10: 433.33333 | AC10: =(AD10*W10)/1000 -> 0 | AD10: =LEFT(details!E10,5) -> 20.00 | AE10: =AA10 -> 433.33333 | AF10: =VLOOKUP(C10,MC.5!B:P,15,FALSE)/3 -> 433.33333 | AG10: =AE10 -> 433.33333 | AH10: =VLOOKUP(F10,REF!B:C,2,FALSE) -> PET | AI10: =VLOOKUP(G10,REF!E:F,2,FALSE) -> Bottle
A11: FG | B11: FG | C11: 322394 | D11: BX38-0100-C-R-AM | E11: 20.000 G | F11: 60104 | G11: 601041000B | H11: 601041000B90000000 | I11: 601041000B90000000 | J11: Others | K11: 0 | L11: 0 | M11: 1440 | N11: 302.4 | O11: 0 | P11: 0 | Q11: 0 | R11: 0 | S11: 0 | T11: 0 | U11: 0 | V11: 0 | W11: 1440 | X11: 302.4 | Y11: 0 | AB11: 0 | AC11: =(AD11*W11)/1000 -> 28.8 | AD11: =LEFT(details!E11,5) -> 20.00 | AE11: =AA11 -> 0 | AF11: =VLOOKUP(C11,MC.5!B:P,15,FALSE)/3 -> 0 | AG11: =AF11 -> 0 | AH11: =VLOOKUP(F11,REF!B:C,2,FALSE) -> PET | AI11: =VLOOKUP(G11,REF!E:F,2,FALSE) -> Bottle
A12: FG | B12: FG | C12: 322405 | D12: BX38-0150-C-R-CL | E12: 20.000 G | F12: 60104 | G12: 601041000B | H12: 601041000B90000000 | I12: 601041000B90000000 | J12: Others | Z12: 883.2 | AA12: 294.4 | AC12: =(AD12*W12)/1000 -> 0 | AD12: =LEFT(details!E12,5) -> 20.00 | AE12: =AA12 -> 294.4 | AF12: =VLOOKUP(C12,MC.5!B:P,15,FALSE)/3 -> 294.4 | AG12: =AE12 -> 294.4 | AH12: =VLOOKUP(F12,REF!B:C,2,FALSE) -> PET | AI12: =VLOOKUP(G12,REF!E:F,2,FALSE) -> Bottle
A13: FG | B13: FG | C13: 322409 | D13: JJ63-0190-E-Q-CL-LW | E13: 24.000 G | F13: 60104 | G13: 601041000J | H13: 601041000J90000000 | I13: 601041000J90000000 | J13: Others | K13: 47814 | L13: 10040.94 | M13: 0 | N13: 0 | O13: 0 | P13: 0 | Q13: 0 | R13: 0 | S13: 0 | T13: 0 | U13: 0 | V13: 0 | W13: 47814 | X13: 10040.94 | Y13: 0 | Z13: 3303.71 | AA13: 1101.2367 | AB13: 273.5363 | AC13: =(AD13*W13)/1000 -> 1147.536 | AD13: =LEFT(details!E13,5) -> 24.00 | AE13: =AA13 -> 1101.2367 | AF13: =VLOOKUP(C13,MC.5!B:P,15,FALSE)/3 -> 3275.98 | AG13: =AE13 -> 1101.2367 | AH13: =VLOOKUP(F13,REF!B:C,2,FALSE) -> PET | AI13: =VLOOKUP(G13,REF!E:F,2,FALSE) -> Jar /Container/Tub
A14: FG | B14: FG | C14: 322411 | D14: JJ63-0200-S-Q-CL | E14: 24.000 G | F14: 60104 | G14: 601041000J | H14: 601041000J90000000 | I14: 601041000J90000000 | J14: Others | K14: 0 | L14: 0 | M14: 0 | N14: 0 | O14: 9720 | P14: 2041.2 | Q14: 0 | R14: 0 | S14: 0 | T14: 0 | U14: 0 | V14: 0 | W14: 9720 | X14: 2041.2 | Y14: 453.64 | Z14: 1090.8 | AA14: 363.6 | AB14: 168.41584 | AC14: =(AD14*W14)/1000 -> 233.28 | AD14: =LEFT(details!E14,5) -> 24.00 | AE14: =AA14 -> 363.6 | AF14: =VLOOKUP(C14,MC.5!B:P,15,FALSE)/3 -> 363.6 | AG14: =AE14 -> 363.6 | AH14: =VLOOKUP(F14,REF!B:C,2,FALSE) -> PET | AI14: =VLOOKUP(G14,REF!E:F,2,FALSE) -> Jar /Container/Tub
A15: FG | B15: FG | C15: 322412 | D15: JJ63-0200-R-R-CL | E15: 24.000 G | F15: 60104 | G15: 601041000J | H15: 601041000J90000000 | I15: 601041000J90000000 | J15: Others | K15: 3045 | L15: 639.45 | M15: 412 | N15: 86.52 | O15: 0 | P15: 0 | Q15: 0 | R15: 0 | S15: 0 | T15: 0 | U15: 0 | V15: 0 | W15: 3457 | X15: 725.97 | Y15: 0 | Z15: 12799.15 | AA15: 4266.3833 | AB15: 5.1048156 | AC15: =(AD15*W15)/1000 -> 82.968 | AD15: =LEFT(details!E15,5) -> 24.00 | AE15: =AA15 -> 4266.3833 | AF15: =VLOOKUP(C15,MC.5!B:P,15,FALSE)/3 -> 4266.3833 | AG15: =AE15 -> 4266.3833 | AH15: =VLOOKUP(F15,REF!B:C,2,FALSE) -> PET | AI15: =VLOOKUP(G15,REF!E:F,2,FALSE) -> Jar /Container/Tub
A16: FG | B16: FG | C16: 322419 | D16: JJ63-0240-R-R-CL | E16: 24.800 G | F16: 60104 | G16: 601041000J | H16: 601041000J90000000 | I16: 601041000J90000000 | J16: Others | K16: 10800 | L16: 2268 | M16: 0 | N16: 0 | O16: 0 | P16: 0 | Q16: 0 | R16: 0 | S16: 0 | T16: 0 | U16: 0 | V16: 0 | W16: 10800 | X16: 2268 | Y16: 0 | Z16: 2196 | AA16: 732 | AB16: 92.95082 | AC16: =(AD16*W16)/1000 -> 267.84 | AD16: =LEFT(details!E16,5) -> 24.80 | AE16: =AA16 -> 732 | AF16: =VLOOKUP(C16,MC.5!B:P,15,FALSE)/3 -> 732 | AG16: =AE16 -> 732 | AH16: =VLOOKUP(F16,REF!B:C,2,FALSE) -> PET | AI16: =VLOOKUP(G16,REF!E:F,2,FALSE) -> Jar /Container/Tub
A17: FG | B17: FG | C17: 322420 | D17: JJ63-0240-RS-R-CL | E17: 24.800 G | F17: 60104 | G17: 601041000J | H17: 601041000J90000000 | I17: 601041000J90000000 | J17: Others | Z17: 3931.21 | AA17: 1310.4033 | AC17: =(AD17*W17)/1000 -> 0 | AD17: =LEFT(details!E17,5) -> 24.80 | AE17: =AA17 -> 1310.4033 | AF17: =VLOOKUP(C17,MC.5!B:P,15,FALSE)/3 -> 1310.4 | AG17: =AE17 -> 1310.4033 | AH17: =VLOOKUP(F17,REF!B:C,2,FALSE) -> PET | AI17: =VLOOKUP(G17,REF!E:F,2,FALSE) -> Jar /Container/Tub
A18: FG | B18: FG | C18: 322422 | D18: JJ63-0250-S-Q-CL-HW | E18: 34.000 G | F18: 60104 | G18: 601041000J | H18: 601041000J90000000 | I18: 601041000J90000000 | J18: Others | K18: 9000 | L18: 2430 | M18: 0 | N18: 0 | O18: 0 | P18: 0 | Q18: 0 | R18: 0 | S18: 0 | T18: 0 | U18: 0 | V18: 0 | W18: 9000 | X18: 2430 | Y18: 0 | Z18: 2430 | AA18: 810 | AB18: 90 | AC18: =(AD18*W18)/1000 -> 306 | AD18: =LEFT(details!E18,5) -> 34.00 | AE18: =AA18 -> 810 | AF18: =VLOOKUP(C18,MC.5!B:P,15,FALSE)/3 -> 810 | AG18: =AE18 -> 810 | AH18: =VLOOKUP(F18,REF!B:C,2,FALSE) -> PET | AI18: =VLOOKUP(G18,REF!E:F,2,FALSE) -> Jar /Container/Tub
A19: FG | B19: FG | C19: 322424 | D19: JJ63-0270-E-Q-CL | E19: 34.500 G | F19: 60104 | G19: 601041000J | H19: 601041000J90000000 | I19: 601041000J90000000 | J19: Others | Z19: 2520 | AA19: 840 | AC19: =(AD19*W19)/1000 -> 0 | AD19: =LEFT(details!E19,5) -> 34.50 | AE19: =AA19 -> 840 | AF19: =VLOOKUP(C19,MC.5!B:P,15,FALSE)/3 -> 840 | AG19: =AE19 -> 840 | AH19: =VLOOKUP(F19,REF!B:C,2,FALSE) -> PET | AI19: =VLOOKUP(G19,REF!E:F,2,FALSE) -> Jar /Container/Tub
A20: FG | B20: FG | C20: 322428 | D20: BC28-0300-PC-R-CL | E20: 23.000 G | F20: 60104 | G20: 601041000B | H20: 601041000B90000000 | I20: 601041000B90000000 | J20: Others | K20: 7560 | L20: 1512 | M20: 0 | N20: 0 | O20: 0 | P20: 0 | Q20: 0 | R20: 0 | S20: 0 | T20: 0 | U20: 0 | V20: 0 | W20: 7560 | X20: 1512 | Y20: 0 | Z20: 5846.4 | AA20: 1948.8 | AB20: 23.275862 | AC20: =(AD20*W20)/1000 -> 173.88 | AD20: =LEFT(details!E20,5) -> 23.00 | AE20: =AA20 -> 1948.8 | AF20: =VLOOKUP(C20,MC.5!B:P,15,FALSE)/3 -> 1948.8 | AG20: =AE20 -> 1948.8 | AH20: =VLOOKUP(F20,REF!B:C,2,FALSE) -> PET | AI20: =VLOOKUP(G20,REF!E:F,2,FALSE) -> Bottle
A21: FG | B21: FG | C21: 322429 | D21: JJ63-0300-R-R-CL | E21: 24.000 G | F21: 60104 | G21: 601041000J | H21: 601041000J90000000 | I21: 601041000J90000000 | J21: Others | K21: 10150 | L21: 2030 | M21: 0 | N21: 0 | O21: 0 | P21: 0 | Q21: 0 | R21: 0 | S21: 0 | T21: 0 | U21: 0 | V21: 0 | W21: 10150 | X21: 2030 | Y21: 0 | Z21: 5653.55 | AA21: 1884.5167 | AB21: 32.315978 | AC21: =(AD21*W21)/1000 -> 243.6 | AD21: =LEFT(details!E21,5) -> 24.00 | AE21: =AA21 -> 1884.5167 | AF21: =VLOOKUP(C21,MC.5!B:P,15,FALSE)/3 -> 1884.5167 | AG21: =AE21 -> 1884.5167 | AH21: =VLOOKUP(F21,REF!B:C,2,FALSE) -> PET | AI21: =VLOOKUP(G21,REF!E:F,2,FALSE) -> Jar /Container/Tub
A22: FG | B22: FG | C22: 322435 | D22: JJ63-0350-NH-R-CL | E22: 34.500 G | F22: 60104 | G22: 601041000J | H22: 601041000J90000000 | I22: 601041000J90000000 | J22: Others | K22: 0 | L22: 0 | M22: 2940 | N22: 793.8 | O22: 0 | P22: 0 | Q22: 0 | R22: 0 | S22: 0 | T22: 0 | U22: 0 | V22: 0 | W22: 2940 | X22: 793.8 | Y22: 0 | Z22: 6312.6 | AA22: 2104.2 | AB22: 11.317365 | AC22: =(AD22*W22)/1000 -> 101.43 | AD22: =LEFT(details!E22,5) -> 34.50 | AE22: =AA22 -> 2104.2 | AF22: =VLOOKUP(C22,MC.5!B:P,15,FALSE)/3 -> 2104.2 | AG22: =AE22 -> 2104.2 | AH22: =VLOOKUP(F22,REF!B:C,2,FALSE) -> PET | AI22: =VLOOKUP(G22,REF!E:F,2,FALSE) -> Jar /Container/Tub
A23: FG | B23: FG | C23: 322436 | D23: JJ63-0350-R-R-CL | E23: 32.820 G | F23: 60104 | G23: 601041000J | H23: 601041000J90000000 | I23: 601041000J90000000 | J23: Others | K23: 0 | L23: 0 | M23: 0 | N23: 0 | O23: 19285 | P23: 4821.25 | Q23: 0 | R23: 0 | S23: 0 | T23: 0 | U23: 0 | V23: 0 | W23: 19285 | X23: 4821.25 | Y23: 803.61 | Z23: 223.3 | AA23: 74.433333 | AB23: 1943.1818 | AC23: =(AD23*W23)/1000 -> 632.9337 | AD23: =LEFT(details!E23,5) -> 32.82 | AE23: =AA23 -> 74.433333 | AF23: =VLOOKUP(C23,MC.5!B:P,15,FALSE)/3 -> 74.433333 | AG23: =AE23 -> 74.433333 | AH23: =VLOOKUP(F23,REF!B:C,2,FALSE) -> PET | AI23: =VLOOKUP(G23,REF!E:F,2,FALSE) -> Jar /Container/Tub
A24: FG | B24: FG | C24: 322438 | D24: BC28-0355-A-Q-CL | E24: 23.000 G | F24: 60104 | G24: 601041000B | H24: 601041000B90000000 | I24: 601041000B90000000 | J24: Others | K24: 35532 | L24: 7817.04 | M24: 0 | N24: 0 | O24: 0 | P24: 0 | Q24: 0 | R24: 0 | S24: 0 | T24: 0 | U24: 0 | V24: 0 | W24: 35532 | X24: 7817.04 | Y24: 0 | Z24: 10862.65 | AA24: 3620.8833 | AB24: 64.766296 | AC24: =(AD24*W24)/1000 -> 817.236 | AD24: =LEFT(details!E24,5) -> 23.00 | AE24: =AA24 -> 3620.8833 | AF24: =VLOOKUP(C24,MC.5!B:P,15,FALSE)/3 -> 3620.88 | AG24: =AE24 -> 3620.8833 | AH24: =VLOOKUP(F24,REF!B:C,2,FALSE) -> PET | AI24: =VLOOKUP(G24,REF!E:F,2,FALSE) -> Bottle
A25: FG | B25: FG | C25: 322442 | D25: JJ63-0400-EH-R-CL | E25: 34.500 G | F25: 60104 | G25: 601041000J | H25: 601041000J90000000 | I25: 601041000J90000000 | J25: Others | K25: 0 | L25: 0 | M25: 0 | N25: 0 | O25: 0 | P25: 0 | Q25: 6180 | R25: 1545 | S25: 660 | T25: 165 | U25: 0 | V25: 0 | W25: 6840 | X25: 1710 | Y25: 1195.08 | Z25: 2066.4 | AA25: 688.8 | AB25: 74.477352 | AC25: =(AD25*W25)/1000 -> 235.98 | AD25: =LEFT(details!E25,5) -> 34.50 | AE25: =AA25 -> 688.8 | AF25: =VLOOKUP(C25,MC.5!B:P,15,FALSE)/3 -> 688.8 | AG25: =AE25 -> 688.8 | AH25: =VLOOKUP(F25,REF!B:C,2,FALSE) -> PET | AI25: =VLOOKUP(G25,REF!E:F,2,FALSE) -> Jar /Container/Tub
A26: FG | B26: FG | C26: 322444 | D26: JJ63-0400-RH-R-CL | E26: 34.500 G | F26: 60104 | G26: 601041000J | H26: 601041000J90000000 | I26: 601041000J90000000 | J26: Others | K26: 7476 | L26: 1943.76 | M26: 0 | N26: 0 | O26: 0 | P26: 0 | Q26: 0 | R26: 0 | S26: 0 | T26: 0 | U26: 0 | V26: 0 | W26: 7476 | X26: 1943.76 | Y26: 0 | Z26: 7636.44 | AA26: 2545.48 | AB26: 22.908371 | AC26: =(AD26*W26)/1000 -> 257.922 | AD26: =LEFT(details!E26,5) -> 34.50 | AE26: =AA26 -> 2545.48 | AF26: =VLOOKUP(C26,MC.5!B:P,15,FALSE)/3 -> 2545.48 | AG26: =AE26 -> 2545.48 | AH26: =VLOOKUP(F26,REF!B:C,2,FALSE) -> PET | AI26: =VLOOKUP(G26,REF!E:F,2,FALSE) -> Jar /Container/Tub
A27: FG | B27: FG | C27: 322445 | D27: JJ63-0400-SH-S-CL | E27: 33.000 G | F27: 60104 | G27: 601041000J | H27: 601041000J90000000 | I27: 601041000J90000000 | J27: Others | K27: 83700 | L27: 22599 | M27: 0 | N27: 0 | O27: 0 | P27: 0 | Q27: 0 | R27: 0 | S27: 0 | T27: 0 | U27: 0 | V27: 0 | W27: 83700 | X27: 22599 | Y27: 0 | Z27: 25137 | AA27: 8379 | AB27: 80.912997 | AC27: =(AD27*W27)/1000 -> 2762.1 | AD27: =LEFT(details!E27,5) -> 33.00 | AE27: =AA27 -> 8379 | AF27: =VLOOKUP(C27,MC.5!B:P,15,FALSE)/3 -> 8379 | AG27: =AE27 -> 8379 | AH27: =VLOOKUP(F27,REF!B:C,2,FALSE) -> PET | AI27: =VLOOKUP(G27,REF!E:F,2,FALSE) -> Jar /Container/Tub
A28: FG | B28: FG | C28: 322448 | D28: BCY28-0500-W-R-CL | E28: 40.600 G | F28: 60104 | G28: 601041000B | H28: 601041000B90000000 | I28: 601041000B90000000 | J28: Others | K28: 25110 | L28: 8537.4 | M28: 0 | N28: 0 | O28: 0 | P28: 0 | Q28: 0 | R28: 0 | S28: 0 | T28: 0 | U28: 0 | V28: 0 | W28: 25110 | X28: 8537.4 | Y28: 0 | Z28: 88063.2 | AA28: 29354.4 | AB28: 8.7251656 | AC28: =(AD28*W28)/1000 -> 1019.466 | AD28: =LEFT(details!E28,5) -> 40.60 | AE28: =AA28 -> 29354.4 | AF28: =VLOOKUP(C28,MC.5!B:P,15,FALSE)/3 -> 29354.4 | AG28: =AE28 -> 29354.4 | AH28: =VLOOKUP(F28,REF!B:C,2,FALSE) -> PET | AI28: =VLOOKUP(G28,REF!E:F,2,FALSE) -> Bottle
A29: FG | B29: FG | C29: 322451 | D29: BC28-0500-WNHP-R-BR | E29: 45.600 G | F29: 60104 | G29: 601041000B | H29: 601041000B90000000 | I29: 601041000B90000000 | J29: Others | K29: 0 | L29: 0 | M29: 4032 | N29: 1653.12 | O29: 0 | P29: 0 | Q29: 0 | R29: 0 | S29: 0 | T29: 0 | U29: 0 | V29: 0 | W29: 4032 | X29: 1653.12 | Y29: 0 | Z29: 9681.84 | AA29: 3227.28 | AB29: 15.366996 | AC29: =(AD29*W29)/1000 -> 183.8592 | AD29: =LEFT(details!E29,5) -> 45.60 | AE29: =AA29 -> 3227.28 | AF29: =VLOOKUP(C29,MC.5!B:P,15,FALSE)/3 -> 3227.28 | AG29: =AE29 -> 3227.28 | AH29: =VLOOKUP(F29,REF!B:C,2,FALSE) -> PET | AI29: =VLOOKUP(G29,REF!E:F,2,FALSE) -> Bottle
A30: FG | B30: FG | C30: 322452 | D30: JJ63-0500-RH-R-CL | E30: 34.500 G | F30: 60104 | G30: 601041000J | H30: 601041000J90000000 | I30: 601041000J90000000 | J30: Others | K30: 29942 | L30: 7485.5 | M30: 0 | N30: 0 | O30: 0 | P30: 0 | Q30: 0 | R30: 0 | S30: 0 | T30: 0 | U30: 0 | V30: 0 | W30: 29942 | X30: 7485.5 | Y30: 0 | Z30: 14426.88 | AA30: 4808.96 | AB30: 46.697207 | AC30: =(AD30*W30)/1000 -> 1032.999 | AD30: =LEFT(details!E30,5) -> 34.50 | AE30: =AA30 -> 4808.96 | AF30: =VLOOKUP(C30,MC.5!B:P,15,FALSE)/3 -> 4809.7933 | AG30: =AE30 -> 4808.96 | AH30: =VLOOKUP(F30,REF!B:C,2,FALSE) -> PET | AI30: =VLOOKUP(G30,REF!E:F,2,FALSE) -> Jar /Container/Tub
A31: FG | B31: FG | C31: 322454 | D31: JJ63-0500-S-Q-CL | E31: 34.500 G | F31: 60104 | G31: 601041000J | H31: 601041000J90000000 | I31: 601041000J90000000 | J31: Others | Z31: 2772 | AA31: 924 | AC31: =(AD31*W31)/1000 -> 0 | AD31: =LEFT(details!E31,5) -> 34.50 | AE31: =AA31 -> 924 | AF31: =VLOOKUP(C31,MC.5!B:P,15,FALSE)/3 -> 924 | AG31: =AE31 -> 924 | AH31: =VLOOKUP(F31,REF!B:C,2,FALSE) -> PET | AI31: =VLOOKUP(G31,REF!E:F,2,FALSE) -> Jar /Container/Tub
A32: FG | B32: FG | C32: 322471 | D32: JJ63-0750-HX-H-CL-LW | E32: 34.500 G | F32: 60104 | G32: 601041000J | H32: 601041000J90000000 | I32: 601041000J90000000 | J32: Others | K32: 2772 | L32: 776.16 | M32: 0 | N32: 0 | O32: 0 | P32: 0 | Q32: 0 | R32: 0 | S32: 0 | T32: 0 | U32: 0 | V32: 0 | W32: 2772 | X32: 776.16 | Y32: 0 | Z32: 7743.12 | AA32: 2581.04 | AB32: 9.0214797 | AC32: =(AD32*W32)/1000 -> 95.634 | AD32: =LEFT(details!E32,5) -> 34.50 | AE32: =AA32 -> 2581.04 | AF32: =VLOOKUP(C32,MC.5!B:P,15,FALSE)/3 -> 2581.04 | AG32: =AE32 -> 2581.04 | AH32: =VLOOKUP(F32,REF!B:C,2,FALSE) -> PET | AI32: =VLOOKUP(G32,REF!E:F,2,FALSE) -> Jar /Container/Tub
A33: FG | B33: FG | C33: 322474 | D33: JJ63-0850-RH-R-CL | E33: 44.000 G | F33: 60104 | G33: 601041000J | H33: 601041000J90000000 | I33: 601041000J90000000 | J33: Others | K33: 14520 | L33: 5227.2 | M33: 0 | N33: 0 | O33: 0 | P33: 0 | Q33: 0 | R33: 0 | S33: 0 | T33: 0 | U33: 0 | V33: 0 | W33: 14520 | X33: 5227.2 | Y33: 0 | Z33: 9932.87 | AA33: 3310.9567 | AB33: 47.362746 | AC33: =(AD33*W33)/1000 -> 638.88 | AD33: =LEFT(details!E33,5) -> 44.00 | AE33: =AA33 -> 3310.9567 | AF33: =VLOOKUP(C33,MC.5!B:P,15,FALSE)/3 -> 3310.96 | AG33: =AE33 -> 3310.9567 | AH33: =VLOOKUP(F33,REF!B:C,2,FALSE) -> PET | AI33: =VLOOKUP(G33,REF!E:F,2,FALSE) -> Jar /Container/Tub
A34: FG | B34: FG | C34: 322477 | D34: JJ63-1000-E-R-CL | E34: 44.000 G | F34: 60104 | G34: 601041000J | H34: 601041000J90000000 | I34: 601041000J90000000 | J34: Others | K34: 37440 | L34: 13104 | M34: 16335 | N34: 5717.25 | O34: 0 | P34: 0 | Q34: 0 | R34: 0 | S34: 0 | T34: 0 | U34: 0 | V34: 0 | W34: 53775 | X34: 18821.25 | Y34: 0 | Z34: 20774.45 | AA34: 6924.8167 | AB34: 81.53826 | AC34: =(AD34*W34)/1000 -> 2366.1 | AD34: =LEFT(details!E34,5) -> 44.00 | AE34: =AA34 -> 6924.8167 | AF34: =VLOOKUP(C34,MC.5!B:P,15,FALSE)/3 -> 6924.82 | AG34: =AE34 -> 6924.8167 | AH34: =VLOOKUP(F34,REF!B:C,2,FALSE) -> PET | AI34: =VLOOKUP(G34,REF!E:F,2,FALSE) -> Jar /Container/Tub
A35: FG | B35: FG | C35: 322493 | D35: BC28-0280-HD-R-CL-LW | E35: 23.000 G | F35: 60104 | G35: 601041000B | H35: 601041000B90000000 | I35: 601041000B90000000 | J35: Others | Z35: 18972 | AA35: 6324 | AC35: =(AD35*W35)/1000 -> 0 | AD35: =LEFT(details!E35,5) -> 23.00 | AE35: =AA35 -> 6324 | AF35: =VLOOKUP(C35,MC.5!B:P,15,FALSE)/3 -> 6324 | AG35: =AE35 -> 6324 | AH35: =VLOOKUP(F35,REF!B:C,2,FALSE) -> PET | AI35: =VLOOKUP(G35,REF!E:F,2,FALSE) -> Bottle
A36: FG | B36: FG | C36: 322503 | D36: BC28-0500-CSD-R-CL | E36: 44.000 G | F36: 60104 | G36: 601041000B | H36: 601041000B90000000 | I36: 601041000B90000000 | J36: Others | K36: 29584 | L36: 10650.24 | M36: 0 | N36: 0 | O36: 0 | P36: 0 | Q36: 0 | R36: 0 | S36: 0 | T36: 0 | U36: 0 | V36: 0 | W36: 29584 | X36: 10650.24 | Y36: 0 | Z36: 5225.36 | AA36: 1741.7867 | AB36: 183.43647 | AC36: =(AD36*W36)/1000 -> 1301.696 | AD36: =LEFT(details!E36,5) -> 44.00 | AE36: =AA36 -> 1741.7867 | AF36: =VLOOKUP(C36,MC.5!B:P,15,FALSE)/3 -> 1741.7867 | AG36: =AE36 -> 1741.7867 | AH36: =VLOOKUP(F36,REF!B:C,2,FALSE) -> PET | AI36: =VLOOKUP(G36,REF!E:F,2,FALSE) -> Bottle
A37: FG | B37: FG | C37: 322506 | D37: BB38-0500-R-R-CL | E37: 32.000 G | F37: 60104 | G37: 601041000B | H37: 601041000B90000000 | I37: 601041000B90000000 | J37: Others | K37: 13860 | L37: 3880.8 | M37: 0 | N37: 0 | O37: 0 | P37: 0 | Q37: 0 | R37: 0 | S37: 0 | T37: 0 | U37: 0 | V37: 0 | W37: 13860 | X37: 3880.8 | Y37: 0 | Z37: 3224.76 | AA37: 1074.92 | AB37: 108.30946 | AC37: =(AD37*W37)/1000 -> 443.52 | AD37: =LEFT(details!E37,5) -> 32.00 | AE37: =AA37 -> 1074.92 | AF37: =VLOOKUP(C37,MC.5!B:P,15,FALSE)/3 -> 1074.92 | AG37: =AE37 -> 1074.92 | AH37: =VLOOKUP(F37,REF!B:C,2,FALSE) -> PET | AI37: =VLOOKUP(G37,REF!E:F,2,FALSE) -> Bottle
A38: FG | B38: FG | C38: 322509 | D38: BB38-0500-S-S-CL | E38: 32.000 G | F38: 60104 | G38: 601041000B | H38: 601041000B90000000 | I38: 601041000B90000000 | J38: Others | K38: 0 | L38: 0 | M38: 0 | N38: 0 | O38: 37440 | P38: 10483.2 | Q38: 29952 | R38: 8386.56 | S38: 0 | T38: 0 | U38: 0 | V38: 0 | W38: 67392 | X38: 18869.76 | Y38: 6173.93 | Z38: 349.44 | AA38: 116.48 | AB38: 4860 | AC38: =(AD38*W38)/1000 -> 2156.544 | AD38: =LEFT(details!E38,5) -> 32.00 | AE38: =AA38 -> 116.48 | AF38: =VLOOKUP(C38,MC.5!B:P,15,FALSE)/3 -> 116.48 | AG38: =AE38 -> 116.48 | AH38: =VLOOKUP(F38,REF!B:C,2,FALSE) -> PET | AI38: =VLOOKUP(G38,REF!E:F,2,FALSE) -> Bottle
A39: FG | B39: FG | C39: 322517 | D39: BB38-1000-HC-S-CL | E39: 45.300 G | F39: 60104 | G39: 601041000B | H39: 601041000B90000000 | I39: 601041000B90000000 | J39: Others | K39: 16250 | L39: 5525 | M39: 0 | N39: 0 | O39: 0 | P39: 0 | Q39: 0 | R39: 0 | S39: 0 | T39: 0 | U39: 0 | V39: 0 | W39: 16250 | X39: 5525 | Y39: 0 | Z39: 8125 | AA39: 2708.3333 | AB39: 61.2 | AC39: =(AD39*W39)/1000 -> 736.125 | AD39: =LEFT(details!E39,5) -> 45.30 | AE39: =AA39 -> 2708.3333 | AF39: =VLOOKUP(C39,MC.5!B:P,15,FALSE)/3 -> 2708.3333 | AG39: =AE39 -> 2708.3333 | AH39: =VLOOKUP(F39,REF!B:C,2,FALSE) -> PET | AI39: =VLOOKUP(G39,REF!E:F,2,FALSE) -> Bottle
A40: FG | B40: FG | C40: 322527 | D40: BB38-1000-S-S-CL | E40: 45.300 G | F40: 60104 | G40: 601041000B | H40: 601041000B90000000 | I40: 601041000B90000000 | J40: Others | K40: 10780 | L40: 3880.8 | M40: 0 | N40: 0 | O40: 0 | P40: 0 | Q40: 530 | R40: 190.8 | S40: 0 | T40: 0 | U40: 0 | V40: 0 | W40: 11310 | X40: 4071.6 | Y40: 84.81 | Z40: 8354.5 | AA40: 2784.8333 | AB40: 43.861871 | AC40: =(AD40*W40)/1000 -> 512.343 | AD40: =LEFT(details!E40,5) -> 45.30 | AE40: =AA40 -> 2784.8333 | AF40: =VLOOKUP(C40,MC.5!B:P,15,FALSE)/3 -> 2784.8333 | AG40: =AE40 -> 2784.8333 | AH40: =VLOOKUP(F40,REF!B:C,2,FALSE) -> PET | AI40: =VLOOKUP(G40,REF!E:F,2,FALSE) -> Bottle
A41: FG | B41: FG | C41: 322535 | D41: Z-HANDLE - YELLOW | E41: 11.390 G | F41: 60106 | G41: 601061000C | H41: 601061000C90000000 | I41: 601061000C90000000 | J41: Others | K41: 0 | L41: 0 | M41: 0 | N41: 0 | O41: 359 | P41: 40.93 | Q41: 0 | R41: 0 | S41: 0 | T41: 0 | U41: 0 | V41: 0 | W41: 359 | X41: 40.93 | Y41: 4.55 | AB41: 0 | AC41: =(AD41*W41)/1000 -> 4.08901 | AD41: =LEFT(details!E41,5) -> 11.39 | AE41: =AA41 -> 0 | AF41: =VLOOKUP(C41,MC.5!B:P,15,FALSE)/3 -> 0 | AG41: =AF41 -> 0 | AH41: =VLOOKUP(F41,REF!B:C,2,FALSE) -> PP | AI41: =VLOOKUP(G41,REF!E:F,2,FALSE) -> Closure/Lid/ Handle
...

Sheet 712 MC.5 2024.08
A1: Plant | B1: Material | C1: Material Type | D1: Material Group | E1: ValStckVal | F1: ValStckVal | G1: Val. stock | H1: Val. stock | I1: LstReceipt | J1: Last GI | K1: Val.stk(I) | L1: Val.stk(I) | M1: Val.stk(R) | N1: Val.stk(R) | O1: CovValStkV | P1: ValStkTurn | Q1: Tot.us.val | R1: Tot.us.val
A2: 712 JJPM-SG BULOH | B2: 322380 BC28-0060-M-R-WH-LW | C2: ZUNI Universal Material Type | D2: FG Finish/Trading Mat | E2: 0 | F2: MYR | G2: 0 | H2: PCE | I2: 44536 | J2: 44558 | K2: 0 | L2: PCE | M2: 0 | N2: PCE | O2: 0 | P2: 0 | Q2: 0 | R2: MYR
A3: 712 JJPM-SG BULOH | B3: 322382 BC28-0060-M-R-CL-LW | C3: ZUNI Universal Material Type | D3: FG Finish/Trading Mat | E3: 0 | F3: MYR | G3: 0 | H3: PCE | I3: 45141 | J3: 45146 | K3: 0 | L3: PCE | M3: 0 | N3: PCE | O3: 0 | P3: 0 | Q3: 0 | R3: MYR
A4: 712 JJPM-SG BULOH | B4: 322383 BB38-0060-R-R-CL | C4: ZUNI Universal Material Type | D4: FG Finish/Trading Mat | E4: 5775 | F4: MYR | G4: 38500 | H4: PCE | I4: 45517 | K4: 68200 | L4: PCE | M4: 52800 | N4: PCE | O4: 53 | P4: 2.12 | Q4: 9955 | R4: MYR
