Workbook
Name DATA10: #REF!
Name DATA11: #REF!
Name DATA12: #REF!
Name DATA2: #REF!
Name DATA3: #REF!
Name DATA4: #REF!
Name DATA5: #REF!
Name DATA6: #REF!
Name DATA7: #REF!
Name DATA8: #REF!
Name DATA9: #REF!
Name TEST1: #REF!
Name TESTHKEY: #REF!
Name TESTKEYS: #REF!
Name TESTVKEY: #REF!

Sheet Daily Report
N1: 0
C2: Supvs Morning | D2: Taufik | AP2: Night | AX2: 262.5 | BR2: 11.736875 | BV2: 7.2943087 | DN2: =#REF! -> #REF!
C3: Supvs Night | D3: Nagin | DN3: Summary Production Machine Efficiency
A4: Date | B4: M/C No | C4: PACKER NAME | D4: Material Type | E4: Sap No. | F4: Product Code | G4: JO No. (Prod. Order No.) | I4: Cav | J4: Gross Weight (gm) | K4: Net Weight (gm) | L4: SHORT | M4: Qty Order (pcs) | N4: WIP Opening (pcs) | O4: WIP Closing (pcs) | P4: Shift Output | Q4: Finish Good (Inward-pcs) To Warehouse | R4: Inward to W/H (kg) | S4: Accumulate Qty Build(pcs) | T4: Balance Qty (pcs) | U4: Material Used (kg) | V4: Runner-Kg | W4: Start up(kg) | X4: Start up (%) | Y4: Prod Reject | Z4: Prod. Reject (%) | AA4: Actual CT (s) | AB4: Run Hours | AC4: SAP Target CT (s) | AD4: Mold Set Up Time (hrs) | AG4: M/C DT (hrs) | AI4: Idle DT | AJ4: Remark | AU4: PROD REJECT | AV4: 0010 (PCS) | AX4: FG | AY4: 0020(PCS) | BC4: For YPP34 0010 | CH4: For YPP34 0020 | DN4: Machine | DO4: Product | DP4: Plan Output | DQ4: Shift Output | DR4: Eff% | DS4: Process Wastages-kg | DT4: Process Wastages % | DU4: Total D'time Hours | DV4: Total Mold Set-Up- Hours | DW4: REJECTION % | DY4: Remark
AD5: FS | AE5: HS | AF5: BM | AG5: MTC | AH5: TECH | AI5: Prod / QC /Other | AK5: Part Scrap | AL5: Labelling Reject | AM5: Purging | AN5: Preform | AO5: Material Descrepancy Inward vs Material Used | AP5: Shift | AQ5: Shift Date Start | AR5: Shift Time Start | AS5: Shift Date End | AT5: Shift Time End | AU5: (PCS) | AV5: Before Yields | AW5: 1 hours Tgt | AX5: Run Hours | AY5: D'TIME Hrs | AZ5: FG Inwards | BA5: Reject (PCS) | BB5: Reject (%) | BC5: Plant | BD5: Posting Date | BE5: Prod Order | BF5: Operation | BG5: Material | BH5: Mat Description | BI5: Start Date | BJ5: Start time | BK5: Finish Date | BL5: Finish time | BM5: Yield Qty | BN5: Scrap Qty | BO5: Un | BP5: Setup | BQ5: Unit | BR5: Machine | BS5: Unit | BT5: Labor | BU5: UOM | BV5: Water/Elect | BW5: UOM | BX5: Fuel(H)/Packing(UN) | BY5: Unit | BZ5: Downtime | CA5: Unit | CB5: Reason for Variance | CC5: Personnel No. | CD5: Confirmation text | CE5: Final Confirmation checkbox | CF5: Clear open reservation checkbox | CG5: Expiry Date (only for ITA plant) | CH5: Plant | CI5: Posting Date | CJ5: Prod Order | CK5: Operation | CL5: Material | CM5: Mat Description | CN5: Start Date | CO5: Start time | CP5: Finish Date | CQ5: Finish time | CR5: Yield Qty | CS5: Scrap Qty | CT5: Un | CU5: Setup | CV5: Unit | CW5: Machine | CX5: Unit | CY5: Labor | CZ5: UOM | DA5: Water/Elect | DB5: UOM | DC5: Fuel(H)/Packing(UN) | DD5: Unit | DE5: Downtime | DF5: Unit | DG5: Reason for Variance | DH5: Personnel No. | DI5: Confirmation text | DJ5: Final Confirmation checkbox | DK5: Clear open reservation checkbox | DL5: Expiry Date (only for ITA plant)
A6: 5M | B6: A5 | C6: RASHIDI | D6: =VLOOKUP(E6,'Reference Card '!A:E,5,FALSE) -> PET | E6: 322471 | F6: =VLOOKUP(E6,'[1]Reference Card '!A:B,2,FALSE) -> JJ63-0750-HX-H-CL-LW | G6: 10703385 | H6: - | I6: =VLOOKUP(E6,'[1]Reference Card '!A:C,3,FALSE) -> 4 | J6: =VLOOKUP(E6,'[1]Reference Card '!A:H,8,FALSE) -> 34.5 | K6: =VLOOKUP(E6,'[1]Reference Card '!A:F,6,FALSE) -> 34.5 | L6: 1625 | M6: 22176 | N6: 0 | O6: 0 | P6: =L6*I6 -> 6500 | Q6: 6468 | R6: =(Q6*K6)/1000 -> 223.146 | S6: 22176 | T6: =IF(M6="Sample","-",IF(M6="RTFN","-",M6-S6)) -> 0 | U6: =(P6*K6)/1000 -> 224.25 | V6: 0 | W6: 0 | X6: =W6/U6 -> 0 | Y6: 1 | Z6: =Y6/U6 -> 0.0044593088 | AA6: 22.8 | AB6: =AA6/3600*L6 -> 10.291667 | AC6: =VLOOKUP(E6,'[2]Reference Card '!A:I,9,FALSE) -> 16.2 | AJ6: Run well.Stop 4.15pm.c/order. | AM6: 2 | AN6: 5 | AO6: =(U6-R6-W6-Y6-AM6-AN6)-(O6*K6/1000) -> -6.896 | AP6: Morning | AQ6: 05.08.2026 | AR6: 06:00:00 | AS6: 05.08.2026 | AT6: 18:00:00 | AU6: =(Y6+W6+AM6+AN6)*1000/K6 -> 231.88406 | AV6: =Q6+AU6 -> 6699.8841 | AW6: =3600/AA6*I6 -> 631.57895 | AX6: =(AV6/AW6)+AY6 -> 10.60815 | AY6: =AG6+AH6+AI6 -> 0 | AZ6: =Q6 -> 6468 | BA6: =AU6 -> 231.88406 | BB6: =BA6/AZ6 -> 0.035850968 | BC6: 712 | BE6: =G6 -> 10703385 | BF6: 0010 | BG6: =E6 -> 322471 | BH6: =F6 -> JJ63-0750-HX-H-CL-LW | BI6: =AQ6 -> 05.08.2026 | BJ6: =AR6 -> 06:00:00 | BK6: =AS6 -> 05.08.2026 | BL6: =AT6 -> 18:00:00 | BM6: =ROUNDDOWN(Q6+AU6,0) -> 6699 | BN6: 0 | BO6: PCE | BQ6: H | BR6: =(AV6/AW6)+AY6 -> 10.60815 | BS6: H | BT6: =(AV6/AW6)+AY6 -> 10.60815 | BU6: H | BV6: =(AV6/AW6)+AY6 -> 10.60815 | BW6: H | BY6: H | CA6: H | CH6: 712 | CJ6: =G6 -> 10703385 | CK6: 0020 | CL6: =E6 -> 322471 | CM6: =F6 -> JJ63-0750-HX-H-CL-LW | CN6: =AQ6 -> 05.08.2026 | CO6: =AR6 -> 06:00:00 | CP6: =AS6 -> 05.08.2026 | CQ6: =AT6 -> 18:00:00 | CR6: =ROUNDDOWN(AZ6,0) -> 6468 | CS6: =ROUNDDOWN(BA6,0) -> 231 | CT6: PCE | CV6: H | CX6: H | CZ6: H | DB6: H | DD6: H | DF6: H | DN6: =B6 -> A5 | DO6: =F6 -> JJ63-0750-HX-H-CL-LW | DP6: =(3600/AC6)*I6*12*0.98 -> 10453.333 | DQ6: =P6 -> 6500 | DR6: =DQ6/DP6*100 -> 62.181122 | DS6: =Y6 -> 1 | DT6: =Z6 -> 0.0044593088 | DU6: =SUM(AG6:AI6) -> 0 | DV6: =SUM(AD6:AF6) -> 0 | DW6: =Y6+W6+AM6+AN6/U6*100 -> 5.2296544 | DY6: =AJ6 -> Run well.Stop 4.15pm.c/order.
A7: 5M | B7: A5 | C7: NA | D7: =VLOOKUP(E7,'Reference Card '!A:E,5,FALSE) -> PET | E7: 324173 | F7: =VLOOKUP(E7,'[1]Reference Card '!A:B,2,FALSE) -> JJ63-0600-RH-R-CL | G7: 10704263 | H7: - | I7: =VLOOKUP(E7,'[1]Reference Card '!A:C,3,FALSE) -> 4 | J7: =VLOOKUP(E7,'[1]Reference Card '!A:H,8,FALSE) -> 34 | K7: =VLOOKUP(E7,'[1]Reference Card '!A:F,6,FALSE) -> 34.5 | L7: 0 | M7: 31500 | N7: 0 | O7: 0 | P7: =L7*I7 -> 0 | Q7: 0 | R7: =(Q7*K7)/1000 -> 0 | S7: 0 | T7: =IF(M7="Sample","-",IF(M7="RTFN","-",M7-S7)) -> 31500 | U7: =(P7*K7)/1000 -> 0 | V7: 0 | W7: 5.5 | X7: =W7/U7 -> #DIV/0! | Y7: 0 | Z7: =Y7/U7 -> #DIV/0! | AA7: 22.8 | AB7: =AA7/3600*L7 -> 0 | AC7: =VLOOKUP(E7,'[2]Reference Card '!A:I,9,FALSE) -> 20.4 | AF7: 1.5 | AH7: 0.25 | AJ7: Start 7.30pm. | AM7: 5 | AN7: 4 | AO7: =(U7-R7-W7-Y7-AM7-AN7)-(O7*K7/1000) -> -14.5 | AP7: Morning | AQ7: 05.08.2026 | AR7: 06:00:00 | AS7: 05.08.2026 | AT7: 18:00:00 | AU7: =(Y7+W7+AM7+AN7)*1000/K7 -> 420.28986 | AV7: =Q7+AU7 -> 420.28986 | AW7: =3600/AA7*I7 -> 631.57895 | AX7: =(AV7/AW7)+AY7 -> 0.91545894 | AY7: =AG7+AH7+AI7 -> 0.25 | AZ7: =Q7 -> 0 | BA7: =AU7 -> 420.28986 | BB7: =BA7/AZ7 -> #DIV/0! | BC7: 712 | BE7: =G7 -> 10704263 | BF7: 0010 | BG7: =E7 -> 324173 | BH7: =F7 -> JJ63-0600-RH-R-CL | BI7: =AQ7 -> 05.08.2026 | BJ7: =AR7 -> 06:00:00 | BK7: =AS7 -> 05.08.2026 | BL7: =AT7 -> 18:00:00 | BM7: =ROUNDDOWN(Q7+AU7,0) -> 420 | BN7: 0 | BO7: PCE | BQ7: H | BR7: =(AV7/AW7)+AY7 -> 0.91545894 | BS7: H | BT7: =(AV7/AW7)+AY7 -> 0.91545894 | BU7: H | BV7: =(AV7/AW7)+AY7 -> 0.91545894 | BW7: H | BY7: H | CA7: H | CH7: 712 | CJ7: =G7 -> 10704263 | CK7: 0020 | CL7: =E7 -> 324173 | CM7: =F7 -> JJ63-0600-RH-R-CL | CN7: =AQ7 -> 05.08.2026 | CO7: =AR7 -> 06:00:00 | CP7: =AS7 -> 05.08.2026 | CQ7: =AT7 -> 18:00:00 | CR7: =ROUNDDOWN(AZ7,0) -> 0 | CS7: =ROUNDDOWN(BA7,0) -> 420 | CT7: PCE | CV7: H | CX7: H | CZ7: H | DB7: H | DD7: H | DF7: H | DN7: =B7 -> A5 | DO7: =F7 -> JJ63-0600-RH-R-CL | DP7: =(3600/AC7)*I7*12*0.98 -> 8301.1765 | DQ7: =P7 -> 0 | DR7: =DQ7/DP7*100 -> 0 | DS7: =Y7 -> 0 | DT7: =Z7 -> #DIV/0! | DU7: =SUM(AG7:AI7) -> 0.25 | DV7: =SUM(AD7:AF7) -> 1.5 | DW7: =Y7+W7+AM7+AN7/U7*100 -> #DIV/0! | DY7: =AJ7 -> Start 7.30pm.
A8: 5M | B8: A6 | C8: KALAMUDIN/PUNES | D8: =VLOOKUP(E8,'Reference Card '!A:E,5,FALSE) -> PET | E8: 322493 | F8: =VLOOKUP(E8,'[1]Reference Card '!A:B,2,FALSE) -> BC28-0280-HD-R-CL-LW | G8: 10704264 | H8: - | I8: =VLOOKUP(E8,'[1]Reference Card '!A:C,3,FALSE) -> 4 | J8: =VLOOKUP(E8,'[1]Reference Card '!A:H,8,FALSE) -> 23 | K8: =VLOOKUP(E8,'[1]Reference Card '!A:F,6,FALSE) -> 23 | L8: 1590 | M8: 30600 | N8: 1275 | O8: 1105 | P8: =L8*I8 -> 6360 | Q8: 6375 | R8: =(Q8*K8)/1000 -> 146.625 | S8: 25330 | T8: =IF(M8="Sample","-",IF(M8="RTFN","-",M8-S8)) -> 5270 | U8: =(P8*K8)/1000 -> 146.28 | V8: =(J8-K8)*P8/1000 -> 0 | W8: 0 | X8: =W8/U8 -> 0 | Y8: 3.5 | Z8: =Y8/U8 -> 0.023926716 | AA8: 26.9 | AB8: =AA8/3600*L8 -> 11.880833 | AC8: =VLOOKUP(E8,'[2]Reference Card '!A:I,9,FALSE) -> 22.5 | AJ8: Base deform.L.test. | AM8: 3 | AN8: 4 | AO8: =(U8-R8-W8-Y8-AM8-AN8)-(O8*K8/1000) -> -36.26 | AP8: Morning | AQ8: 05.08.2026 | AR8: 06:00:00 | AS8: 05.08.2026 | AT8: 18:00:00 | AU8: =(Y8+W8+AM8+AN8)*1000/K8 -> 456.52174 | AV8: =Q8+AU8 -> 6831.5217 | AW8: =3600/AA8*I8 -> 535.31599 | AX8: =(AV8/AW8)+AY8 -> 12.761662 | AY8: =AG8+AH8+AI8 -> 0 | AZ8: =Q8 -> 6375 | BA8: =AU8 -> 456.52174 | BB8: =BA8/AZ8 -> 0.071611253 | BC8: 712 | BE8: =G8 -> 10704264 | BF8: 0010 | BG8: =E8 -> 322493 | BH8: =F8 -> BC28-0280-HD-R-CL-LW | BI8: =AQ8 -> 05.08.2026 | BJ8: =AR8 -> 06:00:00 | BK8: =AS8 -> 05.08.2026 | BL8: =AT8 -> 18:00:00 | BM8: =ROUNDDOWN(Q8+AU8,0) -> 6831 | BN8: 0 | BO8: PCE | BQ8: H | BR8: =(AV8/AW8)+AY8 -> 12.761662 | BS8: H | BT8: =(AV8/AW8)+AY8 -> 12.761662 | BU8: H | BV8: =(AV8/AW8)+AY8 -> 12.761662 | BW8: H | BY8: H | CA8: H | CH8: 712 | CJ8: =G8 -> 10704264 | CK8: 0020 | CL8: =E8 -> 322493 | CM8: =F8 -> BC28-0280-HD-R-CL-LW | CN8: =AQ8 -> 05.08.2026 | CO8: =AR8 -> 06:00:00 | CP8: =AS8 -> 05.08.2026 | CQ8: =AT8 -> 18:00:00 | CR8: =ROUNDDOWN(AZ8,0) -> 6375 | CS8: =ROUNDDOWN(BA8,0) -> 456 | CT8: PCE | CV8: H | CX8: H | CZ8: H | DB8: H | DD8: H | DF8: H | DN8: =B8 -> A6 | DO8: =F8 -> BC28-0280-HD-R-CL-LW | DP8: =(3600/AC8)*I8*12*0.98 -> 7526.4 | DQ8: =P8 -> 6360 | DR8: =DQ8/DP8*100 -> 84.502551 | DS8: =Y8 -> 3.5 | DT8: =Z8 -> 0.023926716 | DU8: =SUM(AG8:AI8) -> 0 | DV8: =SUM(AD8:AF8) -> 0 | DW8: =Y8+W8+AM8+AN8/U8*100 -> 9.2344818 | DY8: =AJ8 -> Base deform.L.test.
A9: 5M | B9: A7 | C9: NA | D9: =VLOOKUP(E9,'Reference Card '!A:E,5,FALSE) -> PET | E9: 324212 | F9: =VLOOKUP(E9,'[1]Reference Card '!A:B,2,FALSE) -> BB38-0250-S-S-CL | G9: 10704834 | H9: - | I9: =VLOOKUP(E9,'[1]Reference Card '!A:C,3,FALSE) -> 4 | J9: =VLOOKUP(E9,'[1]Reference Card '!A:H,8,FALSE) -> 16 | K9: =VLOOKUP(E9,'[1]Reference Card '!A:F,6,FALSE) -> 16 | L9: 0 | M9: 25600 | N9: 0 | O9: 0 | P9: =L9*I9 -> 0 | Q9: 0 | R9: =(Q9*K9)/1000 -> 0 | S9: 0 | T9: =IF(M9="Sample","-",IF(M9="RTFN","-",M9-S9)) -> 25600 | U9: =(P9*K9)/1000 -> 0 | V9: =(J9-K9)*P9/1000 -> 0 | W9: 0 | X9: =W9/U9 -> #DIV/0! | Y9: 0 | Z9: =Y9/U9 -> #DIV/0! | AA9: 26.9 | AB9: =AA9/3600*L9 -> 0 | AC9: =VLOOKUP(E9,'[2]Reference Card '!A:I,9,FALSE) -> 18.32 | AD9: 5.5 | AG9: 4 | AH9: 2.5 | AJ9: mntc service mc oil.Under tech start up. | AO9: =(U9-R9-W9-Y9-AM9-AN9)-(O9*K9/1000) -> 0 | AP9: Morning | AQ9: 05.08.2026 | AR9: 06:00:00 | AS9: 05.08.2026 | AT9: 18:00:00 | AU9: =(Y9+W9+AM9+AN9)*1000/K9 -> 0 | AV9: =Q9+AU9 -> 0 | AW9: =3600/AA9*I9 -> 535.31599 | AX9: =(AV9/AW9)+AY9 -> 6.5 | AY9: =AG9+AH9+AI9 -> 6.5 | AZ9: =Q9 -> 0 | BA9: =AU9 -> 0 | BB9: =BA9/AZ9 -> #DIV/0! | BC9: 712 | BE9: =G9 -> 10704834 | BF9: 0010 | BG9: =E9 -> 324212 | BH9: =F9 -> BB38-0250-S-S-CL | BI9: =AQ9 -> 05.08.2026 | BJ9: =AR9 -> 06:00:00 | BK9: =AS9 -> 05.08.2026 | BL9: =AT9 -> 18:00:00 | BM9: =ROUNDDOWN(Q9+AU9,0) -> 0 | BN9: 0 | BO9: PCE | BQ9: H | BR9: =(AV9/AW9)+AY9 -> 6.5 | BS9: H | BT9: =(AV9/AW9)+AY9 -> 6.5 | BU9: H | BV9: =(AV9/AW9)+AY9 -> 6.5 | BW9: H | BY9: H | CA9: H | CH9: 712 | CJ9: =G9 -> 10704834 | CK9: 0020 | CL9: =E9 -> 324212 | CM9: =F9 -> BB38-0250-S-S-CL | CN9: =AQ9 -> 05.08.2026 | CO9: =AR9 -> 06:00:00 | CP9: =AS9 -> 05.08.2026 | CQ9: =AT9 -> 18:00:00 | CR9: =ROUNDDOWN(AZ9,0) -> 0 | CS9: =ROUNDDOWN(BA9,0) -> 0 | CT9: PCE | CV9: H | CX9: H | CZ9: H | DB9: H | DD9: H | DF9: H | DN9: =B9 -> A7 | DO9: =F9 -> BB38-0250-S-S-CL | DP9: =(3600/AC9)*I9*12*0.98 -> 9243.6681 | DQ9: =P9 -> 0 | DR9: =DQ9/DP9*100 -> 0 | DS9: =Y9 -> 0 | DT9: =Z9 -> #DIV/0! | DU9: =SUM(AG9:AI9) -> 6.5 | DV9: =SUM(AD9:AF9) -> 5.5 | DW9: =Y9+W9+AM9+AN9/U9*100 -> #DIV/0! | DY9: =AJ9 -> mntc service mc oil.Under tech start up.
A10: 5M | B10: A9 | C10: PUNES | D10: =VLOOKUP(E10,'Reference Card '!A:E,5,FALSE) -> PET | E10: 347623 | F10: =VLOOKUP(E10,'[1]Reference Card '!A:B,2,FALSE) -> BC28-0375-K-R-CL | G10: 10704679 | H10: - | I10: =VLOOKUP(E10,'[1]Reference Card '!A:C,3,FALSE) -> 4 | J10: =VLOOKUP(E10,'[1]Reference Card '!A:H,8,FALSE) -> 35.6 | K10: =VLOOKUP(E10,'[1]Reference Card '!A:F,6,FALSE) -> 35.6 | L10: 1674 | M10: 38640 | N10: 5152 | O10: 736 | P10: =L10*I10 -> 6696 | Q10: 11040 | R10: =(Q10*K10)/1000 -> 393.024 | S10: 11776 | T10: =IF(M10="Sample","-",IF(M10="RTFN","-",M10-S10)) -> 26864 | U10: =(P10*K10)/1000 -> 238.3776 | V10: =(J10-K10)*P10/1000 -> 0 | W10: 0 | X10: =W10/U10 -> 0 | Y10: 2.6 | Z10: =Y10/U10 -> 0.010907065 | AA10: 25.4 | AB10: =AA10/3600*L10 -> 11.811 | AC10: =VLOOKUP(E10,'[2]Reference Card '!A:I,9,FALSE) -> 27 | AJ10: Run well.l.test. | AO10: =(U10-R10-W10-Y10-AM10-AN10)-(O10*K10/1000) -> -183.448 | AP10: Morning | AQ10: 05.08.2026 | AR10: 06:00:00 | AS10: 05.08.2026 | AT10: 18:00:00 | AU10: =(Y10+W10+AM10+AN10)*1000/K10 -> 73.033708 | AV10: =Q10+AU10 -> 11113.034 | AW10: =3600/AA10*I10 -> 566.92913 | AX10: =(AV10/AW10)+AY10 -> 19.602157 | AY10: =AG10+AH10+AI10 -> 0 | AZ10: =Q10 -> 11040 | BA10: =AU10 -> 73.033708 | BB10: =BA10/AZ10 -> 0.0066153721 | BC10: 712 | BE10: =G10 -> 10704679 | BF10: 0010 | BG10: =E10 -> 347623 | BH10: =F10 -> BC28-0375-K-R-CL | BI10: =AQ10 -> 05.08.2026 | BJ10: =AR10 -> 06:00:00 | BK10: =AS10 -> 05.08.2026 | BL10: =AT10 -> 18:00:00 | BM10: =ROUNDDOWN(Q10+AU10,0) -> 11113 | BN10: 0 | BO10: PCE | BQ10: H | BR10: =(AV10/AW10)+AY10 -> 19.602157 | BS10: H | BT10: =(AV10/AW10)+AY10 -> 19.602157 | BU10: H | BV10: =(AV10/AW10)+AY10 -> 19.602157 | BW10: H | BY10: H | CA10: H | CH10: 712 | CJ10: =G10 -> 10704679 | CK10: 0020 | CL10: =E10 -> 347623 | CM10: =F10 -> BC28-0375-K-R-CL | CN10: =AQ10 -> 05.08.2026 | CO10: =AR10 -> 06:00:00 | CP10: =AS10 -> 05.08.2026 | CQ10: =AT10 -> 18:00:00 | CR10: =ROUNDDOWN(AZ10,0) -> 11040 | CS10: =ROUNDDOWN(BA10,0) -> 73 | CT10: PCE | CV10: H | CX10: H | CZ10: H | DB10: H | DD10: H | DF10: H | DN10: =B10 -> A9 | DO10: =F10 -> BC28-0375-K-R-CL | DP10: =(3600/AC10)*I10*12*0.98 -> 6272 | DQ10: =P10 -> 6696 | DR10: =DQ10/DP10*100 -> 106.7602 | DS10: =Y10 -> 2.6 | DT10: =Z10 -> 0.010907065 | DU10: =SUM(AG10:AI10) -> 0 | DV10: =SUM(AD10:AF10) -> 0 | DW10: =Y10+W10+AM10+AN10/U10*100 -> 2.6 | DY10: =AJ10 -> Run well.l.test.
A11: 5M | B11: A10 | C11: ZAM/SHAHID | D11: =VLOOKUP(E11,'Reference Card '!A:E,5,FALSE) -> PET | E11: 532981 | F11: =VLOOKUP(E11,'[1]Reference Card '!A:B,2,FALSE) -> JG63-0175-R-R-AM | G11: 10703864 | H11: - | I11: =VLOOKUP(E11,'[1]Reference Card '!A:C,3,FALSE) -> 4 | J11: =VLOOKUP(E11,'[1]Reference Card '!A:H,8,FALSE) -> 24.45 | K11: =VLOOKUP(E11,'[1]Reference Card '!A:F,6,FALSE) -> 24 | L11: 710 | M11: 87552 | N11: 4560 | O11: 1824 | P11: =L11*I11 -> 2840 | Q11: 5472 | R11: =(Q11*K11)/1000 -> 131.328 | S11: 62016 | T11: =IF(M11="Sample","-",IF(M11="RTFN","-",M11-S11)) -> 25536 | U11: =(P11*K11)/1000 -> 68.16 | V11: 0 | W11: 0 | X11: =W11/U11 -> 0 | Y11: 2.5 | Z11: =Y11/U11 -> 0.036678404 | AA11: 22 | AB11: =AA11/3600*L11 -> 4.3388889 | AC11: =VLOOKUP(E11,'[2]Reference Card '!A:I,9,FALSE) -> 20 | AG11: 7 | AJ11: Charging problem.Stop 9am-4pm.Under mntc. | AM11: 12 | AN11: 12 | AO11: =(U11-R11-W11-Y11-AM11-AN11)-(O11*K11/1000) -> -133.444 | AP11: Morning | AQ11: 05.08.2026 | AR11: 06:00:00 | AS11: 05.08.2026 | AT11: 18:00:00 | AU11: =(Y11+W11+AM11+AN11)*1000/K11 -> 1104.1667 | AV11: =Q11+AU11 -> 6576.1667 | AW11: =3600/AA11*I11 -> 654.54545 | AX11: =(AV11/AW11)+AY11 -> 17.046921 | AY11: =AG11+AH11+AI11 -> 7 | AZ11: =Q11 -> 5472 | BA11: =AU11 -> 1104.1667 | BB11: =BA11/AZ11 -> 0.20178484 | BC11: 712 | BE11: =G11 -> 10703864 | BF11: 0010 | BG11: =E11 -> 532981 | BH11: =F11 -> JG63-0175-R-R-AM | BI11: =AQ11 -> 05.08.2026 | BJ11: =AR11 -> 06:00:00 | BK11: =AS11 -> 05.08.2026 | BL11: =AT11 -> 18:00:00 | BM11: =ROUNDDOWN(Q11+AU11,0) -> 6576 | BN11: 0 | BO11: PCE | BQ11: H | BR11: =(AV11/AW11)+AY11 -> 17.046921 | BS11: H | BT11: =(AV11/AW11)+AY11 -> 17.046921 | BU11: H | BV11: =(AV11/AW11)+AY11 -> 17.046921 | BW11: H | BY11: H | CA11: H | CH11: 712 | CJ11: =G11 -> 10703864 | CK11: 0020 | CL11: =E11 -> 532981 | CM11: =F11 -> JG63-0175-R-R-AM | CN11: =AQ11 -> 05.08.2026 | CO11: =AR11 -> 06:00:00 | CP11: =AS11 -> 05.08.2026 | CQ11: =AT11 -> 18:00:00 | CR11: =ROUNDDOWN(AZ11,0) -> 5472 | CS11: =ROUNDDOWN(BA11,0) -> 1104 | CT11: PCE | CV11: H | CX11: H | CZ11: H | DB11: H | DD11: H | DF11: H | DN11: =B11 -> A10 | DO11: =F11 -> JG63-0175-R-R-AM | DP11: =(3600/AC11)*I11*12*0.98 -> 8467.2 | DQ11: =P11 -> 2840 | DR11: =DQ11/DP11*100 -> 33.541194 | DS11: =Y11 -> 2.5 | DT11: =Z11 -> 0.036678404 | DU11: =SUM(AG11:AI11) -> 7 | DV11: =SUM(AD11:AF11) -> 0 | DW11: =Y11+W11+AM11+AN11/U11*100 -> 32.105634 | DY11: =AJ11 -> Charging problem.Stop 9am-4pm.Under mntc.
A12: 5M | B12: A12 | C12: KALAMUDIN | D12: =VLOOKUP(E12,'Reference Card '!A:E,5,FALSE) -> PET | E12: 543590 | F12: =VLOOKUP(E12,'[1]Reference Card '!A:B,2,FALSE) -> BC28-0130-R-R-AM | G12: 10702380 | H12: - | I12: =VLOOKUP(E12,'[1]Reference Card '!A:C,3,FALSE) -> 4 | J12: =VLOOKUP(E12,'[1]Reference Card '!A:H,8,FALSE) -> 19 | K12: =VLOOKUP(E12,'[1]Reference Card '!A:F,6,FALSE) -> 19 | L12: 2086 | M12: 120120 | N12: 2464 | O12: 3388 | P12: =L12*I12 -> 8344 | Q12: 7392 | R12: =(Q12*K12)/1000 -> 140.448 | S12: 99484 | T12: =IF(M12="Sample","-",IF(M12="RTFN","-",M12-S12)) -> 20636 | U12: =(P12*K12)/1000 -> 158.536 | V12: =(J12-K12)*P12/1000 -> 0 | W12: 0 | X12: =W12/U12 -> 0 | Y12: 0.5 | Z12: =Y12/U12 -> 0.0031538578 | AA12: 20.2 | AB12: =AA12/3600*L12 -> 11.704778 | AC12: =VLOOKUP(E12,'[2]Reference Card '!A:I,9,FALSE) -> 18.72 | AJ12: Run well.L.test. | AM12: 5 | AN12: 5 | AO12: =(U12-R12-W12-Y12-AM12-AN12)-(O12*K12/1000) -> -56.784 | AP12: Morning | AQ12: 05.08.2026 | AR12: 06:00:00 | AS12: 05.08.2026 | AT12: 18:00:00 | AU12: =(Y12+W12+AM12+AN12)*1000/K12 -> 552.63158 | AV12: =Q12+AU12 -> 7944.6316 | AW12: =3600/AA12*I12 -> 712.87129 | AX12: =(AV12/AW12)+AY12 -> 11.144553 | AY12: =AG12+AH12+AI12 -> 0 | AZ12: =Q12 -> 7392 | BA12: =AU12 -> 552.63158 | BB12: =BA12/AZ12 -> 0.074760766 | BC12: 712 | BE12: =G12 -> 10702380 | BF12: 0010 | BG12: =E12 -> 543590 | BH12: =F12 -> BC28-0130-R-R-AM | BI12: =AQ12 -> 05.08.2026 | BJ12: =AR12 -> 06:00:00 | BK12: =AS12 -> 05.08.2026 | BL12: =AT12 -> 18:00:00 | BM12: =ROUNDDOWN(Q12+AU12,0) -> 7944 | BN12: 0 | BO12: PCE | BQ12: H | BR12: =(AV12/AW12)+AY12 -> 11.144553 | BS12: H | BT12: =(AV12/AW12)+AY12 -> 11.144553 | BU12: H | BV12: =(AV12/AW12)+AY12 -> 11.144553 | BW12: H | BY12: H | CA12: H | CH12: 712 | CJ12: =G12 -> 10702380 | CK12: 0020 | CL12: =E12 -> 543590 | CM12: =F12 -> BC28-0130-R-R-AM | CN12: =AQ12 -> 05.08.2026 | CO12: =AR12 -> 06:00:00 | CP12: =AS12 -> 05.08.2026 | CQ12: =AT12 -> 18:00:00 | CR12: =ROUNDDOWN(AZ12,0) -> 7392 | CS12: =ROUNDDOWN(BA12,0) -> 552 | CT12: PCE | CV12: H | CX12: H | CZ12: H | DB12: H | DD12: H | DF12: H | DN12: =B12 -> A12 | DO12: =F12 -> BC28-0130-R-R-AM | DP12: =(3600/AC12)*I12*12*0.98 -> 9046.1538 | DQ12: =P12 -> 8344 | DR12: =DQ12/DP12*100 -> 92.238095 | DS12: =Y12 -> 0.5 | DT12: =Z12 -> 0.0031538578 | DU12: =SUM(AG12:AI12) -> 0 | DV12: =SUM(AD12:AF12) -> 0 | DW12: =Y12+W12+AM12+AN12/U12*100 -> 8.6538578 | DY12: =AJ12 -> Run well.L.test.
A13: 5M | B13: A13 | C13: SHAHID | D13: =VLOOKUP(E13,'Reference Card '!A:E,5,FALSE) -> rPET | E13: 593537 | F13: =VLOOKUP(E13,'[1]Reference Card '!A:B,2,FALSE) -> BX38-1000-RN-R-CL-rPET 0.2 | G13: 10704764 | H13: - | I13: =VLOOKUP(E13,'[1]Reference Card '!A:C,3,FALSE) -> 4 | J13: =VLOOKUP(E13,'[1]Reference Card '!A:H,8,FALSE) -> 56.5 | K13: =VLOOKUP(E13,'[1]Reference Card '!A:F,6,FALSE) -> 56.8 | L13: 1501 | M13: 69000 | N13: 3450 | O13: 115 | P13: =L13*I13 -> 6004 | Q13: 9200 | R13: =(Q13*K13)/1000 -> 522.56 | S13: 9315 | T13: =IF(M13="Sample","-",IF(M13="RTFN","-",M13-S13)) -> 59685 | U13: =(P13*K13)/1000 -> 341.0272 | V13: 0 | W13: 0 | X13: =W13/U13 -> 0 | Y13: 7.8 | Z13: =Y13/U13 -> 0.022872076 | AA13: 29 | AB13: =AA13/3600*L13 -> 12.091389 | AC13: =VLOOKUP(E13,'[2]Reference Card '!A:I,9,FALSE) -> 28.5 | AJ13: Lip white mark.L.test. | AO13: =(U13-R13-W13-Y13-AM13-AN13)-(O13*K13/1000) -> -195.8648 | AP13: Morning | AQ13: 05.08.2026 | AR13: 06:00:00 | AS13: 05.08.2026 | AT13: 18:00:00 | AU13: =(Y13+W13+AM13+AN13)*1000/K13 -> 137.32394 | AV13: =Q13+AU13 -> 9337.3239 | AW13: =3600/AA13*I13 -> 496.55172 | AX13: =(AV13/AW13)+AY13 -> 18.804333 | AY13: =AG13+AH13+AI13 -> 0 | AZ13: =Q13 -> 9200 | BA13: =AU13 -> 137.32394 | BB13: =BA13/AZ13 -> 0.014926516 | BC13: 712 | BE13: =G13 -> 10704764 | BF13: 0010 | BG13: =E13 -> 593537 | BH13: =F13 -> BX38-1000-RN-R-CL-rPET 0.2 | BI13: =AQ13 -> 05.08.2026 | BJ13: =AR13 -> 06:00:00 | BK13: =AS13 -> 05.08.2026 | BL13: =AT13 -> 18:00:00 | BM13: =ROUNDDOWN(Q13+AU13,0) -> 9337 | BN13: 0 | BO13: PCE | BQ13: H | BR13: =(AV13/AW13)+AY13 -> 18.804333 | BS13: H | BT13: =(AV13/AW13)+AY13 -> 18.804333 | BU13: H | BV13: =(AV13/AW13)+AY13 -> 18.804333 | BW13: H | BY13: H | CA13: H | CH13: 712 | CJ13: =G13 -> 10704764 | CK13: 0020 | CL13: =E13 -> 593537 | CM13: =F13 -> BX38-1000-RN-R-CL-rPET 0.2 | CN13: =AQ13 -> 05.08.2026 | CO13: =AR13 -> 06:00:00 | CP13: =AS13 -> 05.08.2026 | CQ13: =AT13 -> 18:00:00 | CR13: =ROUNDDOWN(AZ13,0) -> 9200 | CS13: =ROUNDDOWN(BA13,0) -> 137 | CT13: PCE | CV13: H | CX13: H | CZ13: H | DB13: H | DD13: H | DF13: H | DN13: =B13 -> A13 | DO13: =F13 -> BX38-1000-RN-R-CL-rPET 0.2 | DP13: =(3600/AC13)*I13*12*0.98 -> 5941.8947 | DQ13: =P13 -> 6004 | DR13: =DQ13/DP13*100 -> 101.04521 | DS13: =Y13 -> 7.8 | DT13: =Z13 -> 0.022872076 | DU13: =SUM(AG13:AI13) -> 0 | DV13: =SUM(AD13:AF13) -> 0 | DW13: =Y13+W13+AM13+AN13/U13*100 -> 7.8 | DY13: =AJ13 -> Lip white mark.L.test.
A14: 5M | B14: A14 | C14: WIYAH | D14: =VLOOKUP(E14,'Reference Card '!A:E,5,FALSE) -> KingFa NC050 | E14: 666344 | F14: BC28-0056-D-APH-5040-0756-PP | G14: 10703060 | H14: - | I14: =VLOOKUP(E14,'[1]Reference Card '!A:C,3,FALSE) -> 6 | J14: 12.3 | K14: 12.3 | L14: 1564 | M14: 162000 | N14: 4455 | O14: 5670 | P14: =L14*I14 -> 9384 | Q14: 8100 | R14: =(Q14*K14)/1000 -> 99.63 | S14: 119070 | T14: =IF(M14="Sample","-",IF(M14="RTFN","-",M14-S14)) -> 42930 | U14: =(P14*K14)/1000 -> 115.4232 | V14: =(J14-K14)*P14/1000 -> 0 | W14: 0 | X14: =W14/U14 -> 0 | Y14: 0.8 | Z14: =Y14/U14 -> 0.0069310156 | AA14: 27.8 | AB14: =AA14/3600*L14 -> 12.077556 | AC14: =VLOOKUP(E14,'[2]Reference Card '!A:I,9,FALSE) -> 26 | AJ14: Run well.L.test. | AO14: =(U14-R14-W14-Y14-AM14-AN14)-(O14*K14/1000) -> -54.7478 | AP14: Morning | AQ14: 05.08.2026 | AR14: 06:00:00 | AS14: 05.08.2026 | AT14: 18:00:00 | AU14: =(Y14+W14+AM14+AN14)*1000/K14 -> 65.04065 | AV14: =Q14+AU14 -> 8165.0407 | AW14: =3600/AA14*I14 -> 776.97842 | AX14: =(AV14/AW14)+AY14 -> 10.50871 | AY14: =AG14+AH14+AI14 -> 0 | AZ14: =Q14 -> 8100 | BA14: =AU14 -> 65.04065 | BB14: =BA14/AZ14 -> 0.0080297099 | BC14: 712 | BE14: =G14 -> 10703060 | BF14: 0010 | BG14: =E14 -> 666344 | BH14: =F14 -> BC28-0056-D-APH-5040-0756-PP | BI14: =AQ14 -> 05.08.2026 | BJ14: =AR14 -> 06:00:00 | BK14: =AS14 -> 05.08.2026 | BL14: =AT14 -> 18:00:00 | BM14: =ROUNDDOWN(Q14+AU14,0) -> 8165 | BN14: 0 | BO14: PCE | BQ14: H | BR14: =(AV14/AW14)+AY14 -> 10.50871 | BS14: H | BT14: =(AV14/AW14)+AY14 -> 10.50871 | BU14: H | BV14: =(AV14/AW14)+AY14 -> 10.50871 | BW14: H | BY14: H | CA14: H | CH14: 712 | CJ14: =G14 -> 10703060 | CK14: 0020 | CL14: =E14 -> 666344 | CM14: =F14 -> BC28-0056-D-APH-5040-0756-PP | CN14: =AQ14 -> 05.08.2026 | CO14: =AR14 -> 06:00:00 | CP14: =AS14 -> 05.08.2026 | CQ14: =AT14 -> 18:00:00 | CR14: =ROUNDDOWN(AZ14,0) -> 8100 | CS14: =ROUNDDOWN(BA14,0) -> 65 | CT14: PCE | CV14: H | CX14: H | CZ14: H | DB14: H | DD14: H | DF14: H | DN14: =B14 -> A14 | DO14: =F14 -> BC28-0056-D-APH-5040-0756-PP | DP14: =(3600/AC14)*I14*12*0.98 -> 9769.8462 | DQ14: =P14 -> 9384 | DR14: =DQ14/DP14*100 -> 96.050642 | DS14: =Y14 -> 0.8 | DT14: =Z14 -> 0.0069310156 | DU14: =SUM(AG14:AI14) -> 0 | DV14: =SUM(AD14:AF14) -> 0 | DW14: =Y14+W14+AM14+AN14/U14*100 -> 0.8 | DY14: =AJ14 -> Run well.L.test.
A15: 5M | B15: A15 | C15: RAM | D15: =VLOOKUP(E15,'Reference Card '!A:E,5,FALSE) -> PET | E15: 323092 | F15: =VLOOKUP(E15,'[1]Reference Card '!A:B,2,FALSE) -> BX38-1000-GH-R-CL(GREEN) (ASEM) | G15: 10703678 | H15: - | I15: =VLOOKUP(E15,'[1]Reference Card '!A:C,3,FALSE) -> 4 | J15: =VLOOKUP(E15,'[1]Reference Card '!A:H,8,FALSE) -> 48.9 | K15: =VLOOKUP(E15,'[1]Reference Card '!A:F,6,FALSE) -> 48.9 | L15: 1409 | M15: 40950 | N15: 105 | O15: 420 | P15: =L15*I15 -> 5636 | Q15: 5250 | R15: =(Q15*K15)/1000 -> 256.725 | S15: 36645 | T15: =IF(M15="Sample","-",IF(M15="RTFN","-",M15-S15)) -> 4305 | U15: =(P15*K15)/1000 -> 275.6004 | V15: =(J15-K15)*P15/1000 -> 0 | W15: 0 | X15: =W15/U15 -> 0 | Y15: 3.5 | Z15: =Y15/U15 -> 0.012699546 | AA15: 29.1 | AB15: =AA15/3600*L15 -> 11.389417 | AC15: =VLOOKUP(E15,'[2]Reference Card '!A:I,9,FALSE) -> 27.6 | AJ15: Oily mark at lip area. | AM15: 3 | AN15: 7 | AO15: =(U15-R15-W15-Y15-AM15-AN15)-(O15*K15/1000) -> -15.1626 | AP15: Morning | AQ15: 05.08.2026 | AR15: 06:00:00 | AS15: 05.08.2026 | AT15: 18:00:00 | AU15: =(Y15+W15+AM15+AN15)*1000/K15 -> 276.07362 | AV15: =Q15+AU15 -> 5526.0736 | AW15: =3600/AA15*I15 -> 494.84536 | AX15: =(AV15/AW15)+AY15 -> 11.167274 | AY15: =AG15+AH15+AI15 -> 0 | AZ15: =Q15 -> 5250 | BA15: =AU15 -> 276.07362 | BB15: =BA15/AZ15 -> 0.052585451 | BC15: 712 | BE15: =G15 -> 10703678 | BF15: 0010 | BG15: =E15 -> 323092 | BH15: =F15 -> BX38-1000-GH-R-CL(GREEN) (ASEM) | BI15: =AQ15 -> 05.08.2026 | BJ15: =AR15 -> 06:00:00 | BK15: =AS15 -> 05.08.2026 | BL15: =AT15 -> 18:00:00 | BM15: =ROUNDDOWN(Q15+AU15,0) -> 5526 | BN15: 0 | BO15: PCE | BQ15: H | BR15: =(AV15/AW15)+AY15 -> 11.167274 | BS15: H | BT15: =(AV15/AW15)+AY15 -> 11.167274 | BU15: H | BV15: =(AV15/AW15)+AY15 -> 11.167274 | BW15: H | BY15: H | CA15: H | CH15: 712 | CJ15: =G15 -> 10703678 | CK15: 0020 | CL15: =E15 -> 323092 | CM15: =F15 -> BX38-1000-GH-R-CL(GREEN) (ASEM) | CN15: =AQ15 -> 05.08.2026 | CO15: =AR15 -> 06:00:00 | CP15: =AS15 -> 05.08.2026 | CQ15: =AT15 -> 18:00:00 | CR15: =ROUNDDOWN(AZ15,0) -> 5250 | CS15: =ROUNDDOWN(BA15,0) -> 276 | CT15: PCE | CV15: H | CX15: H | CZ15: H | DB15: H | DD15: H | DF15: H | DN15: =B15 -> A15 | DO15: =F15 -> BX38-1000-GH-R-CL(GREEN) (ASEM) | DP15: =(3600/AC15)*I15*12*0.98 -> 6135.6522 | DQ15: =P15 -> 5636 | DR15: =DQ15/DP15*100 -> 91.856576 | DS15: =Y15 -> 3.5 | DT15: =Z15 -> 0.012699546 | DU15: =SUM(AG15:AI15) -> 0 | DV15: =SUM(AD15:AF15) -> 0 | DW15: =Y15+W15+AM15+AN15/U15*100 -> 9.0399092 | DY15: =AJ15 -> Oily mark at lip area.
A16: 5M | B16: A16 | C16: NA | D16: =VLOOKUP(E16,'Reference Card '!A:E,5,FALSE) -> PPSB520Y | E16: 552181 | F16: =VLOOKUP(E16,'[1]Reference Card '!A:B,2,FALSE) -> BC28-0090-D-APH-5180-3538-PP-6 NOTCHES | G16: 10704299 | H16: - | I16: =VLOOKUP(E16,'[1]Reference Card '!A:C,3,FALSE) -> 6 | J16: =VLOOKUP(E16,'[1]Reference Card '!A:H,8,FALSE) -> 14.7 | K16: =VLOOKUP(E16,'[1]Reference Card '!A:F,6,FALSE) -> 14.7 | L16: 0 | M16: 54000 | N16: 5400 | O16: 0 | P16: =L16*I16 -> 0 | Q16: 5400 | R16: =(Q16*K16)/1000 -> 79.38 | S16: 54000 | T16: =IF(M16="Sample","-",IF(M16="RTFN","-",M16-S16)) -> 0 | U16: =(P16*K16)/1000 -> 0 | V16: =(J16-K16)*P16/1000 -> 0 | W16: 0 | X16: =W16/U16 -> #DIV/0! | Y16: 0 | Z16: =Y16/U16 -> #DIV/0! | AA16: 29.8 | AB16: =AA16/3600*L16 -> 0 | AC16: =VLOOKUP(E16,'[2]Reference Card '!A:I,9,FALSE) -> 27 | AJ16: Inward. | AO16: =(U16-R16-W16-Y16-AM16-AN16)-(O16*K16/1000) -> -79.38 | AP16: Morning | AQ16: 05.08.2026 | AR16: 06:00:00 | AS16: 05.08.2026 | AT16: 18:00:00 | AU16: =(Y16+W16+AM16+AN16)*1000/K16 -> 0 | AV16: =Q16+AU16 -> 5400 | AW16: =3600/AA16*I16 -> 724.83221 | AX16: =(AV16/AW16)+AY16 -> 7.45 | AY16: =AG16+AH16+AI16 -> 0 | AZ16: =Q16 -> 5400 | BA16: =AU16 -> 0 | BB16: =BA16/AZ16 -> 0 | BC16: 712 | BE16: =G16 -> 10704299 | BF16: 0010 | BG16: =E16 -> 552181 | BH16: =F16 -> BC28-0090-D-APH-5180-3538-PP-6 NOTCHES | BI16: =AQ16 -> 05.08.2026 | BJ16: =AR16 -> 06:00:00 | BK16: =AS16 -> 05.08.2026 | BL16: =AT16 -> 18:00:00 | BM16: =ROUNDDOWN(Q16+AU16,0) -> 5400 | BN16: 0 | BO16: PCE | BQ16: H | BR16: =(AV16/AW16)+AY16 -> 7.45 | BS16: H | BT16: =(AV16/AW16)+AY16 -> 7.45 | BU16: H | BV16: =(AV16/AW16)+AY16 -> 7.45 | BW16: H | BY16: H | CA16: H | CH16: 712 | CJ16: =G16 -> 10704299 | CK16: 0020 | CL16: =E16 -> 552181 | CM16: =F16 -> BC28-0090-D-APH-5180-3538-PP-6 NOTCHES | CN16: =AQ16 -> 05.08.2026 | CO16: =AR16 -> 06:00:00 | CP16: =AS16 -> 05.08.2026 | CQ16: =AT16 -> 18:00:00 | CR16: =ROUNDDOWN(AZ16,0) -> 5400 | CS16: =ROUNDDOWN(BA16,0) -> 0 | CT16: PCE | CV16: H | CX16: H | CZ16: H | DB16: H | DD16: H | DF16: H | DN16: =B16 -> A16 | DO16: =F16 -> BC28-0090-D-APH-5180-3538-PP-6 NOTCHES | DP16: =(3600/AC16)*I16*12*0.98 -> 9408 | DQ16: =P16 -> 0 | DR16: =DQ16/DP16*100 -> 0 | DS16: =Y16 -> 0 | DT16: =Z16 -> #DIV/0! | DU16: =SUM(AG16:AI16) -> 0 | DV16: =SUM(AD16:AF16) -> 0 | DW16: =Y16+W16+AM16+AN16/U16*100 -> #DIV/0! | DY16: =AJ16 -> Inward.
A17: 5M | B17: A16 | C17: DIPAK | D17: =VLOOKUP(E17,'Reference Card '!A:E,5,FALSE) -> PPSB520Y | E17: 552181 | F17: =VLOOKUP(E17,'[1]Reference Card '!A:B,2,FALSE) -> BC28-0090-D-APH-5180-3538-PP-6 NOTCHES | G17: 10704833 | H17: - | I17: =VLOOKUP(E17,'[1]Reference Card '!A:C,3,FALSE) -> 6 | J17: =VLOOKUP(E17,'[1]Reference Card '!A:H,8,FALSE) -> 14.7 | K17: =VLOOKUP(E17,'[1]Reference Card '!A:F,6,FALSE) -> 14.7 | L17: 862 | M17: 54000 | N17: 5670 | O17: 0 | P17: =L17*I17 -> 5172 | Q17: 10800 | R17: =(Q17*K17)/1000 -> 158.76 | S17: 10800 | T17: =IF(M17="Sample","-",IF(M17="RTFN","-",M17-S17)) -> 43200 | U17: =(P17*K17)/1000 -> 76.0284 | V17: =(J17-K17)*P17/1000 -> 0 | W17: 0 | X17: =W17/U17 -> 0 | Y17: 0.6 | Z17: =Y17/U17 -> 0.0078917878 | AA17: 29.8 | AB17: =AA17/3600*L17 -> 7.1354444 | AC17: =VLOOKUP(E17,'[2]Reference Card '!A:I,9,FALSE) -> 27 | AJ17: Stop 1pm.Change mtrl PCR. | AO17: =(U17-R17-W17-Y17-AM17-AN17)-(O17*K17/1000) -> -83.3316 | AP17: Morning | AQ17: 05.08.2026 | AR17: 06:00:00 | AS17: 05.08.2026 | AT17: 18:00:00 | AU17: =(Y17+W17+AM17+AN17)*1000/K17 -> 40.816327 | AV17: =Q17+AU17 -> 10840.816 | AW17: =3600/AA17*I17 -> 724.83221 | AX17: =(AV17/AW17)+AY17 -> 14.956311 | AY17: =AG17+AH17+AI17 -> 0 | AZ17: =Q17 -> 10800 | BA17: =AU17 -> 40.816327 | BB17: =BA17/AZ17 -> 0.0037792895 | BC17: 712 | BE17: =G17 -> 10704833 | BF17: 0010 | BG17: =E17 -> 552181 | BH17: =F17 -> BC28-0090-D-APH-5180-3538-PP-6 NOTCHES | BI17: =AQ17 -> 05.08.2026 | BJ17: =AR17 -> 06:00:00 | BK17: =AS17 -> 05.08.2026 | BL17: =AT17 -> 18:00:00 | BM17: =ROUNDDOWN(Q17+AU17,0) -> 10840 | BN17: 0 | BO17: PCE | BQ17: H | BR17: =(AV17/AW17)+AY17 -> 14.956311 | BS17: H | BT17: =(AV17/AW17)+AY17 -> 14.956311 | BU17: H | BV17: =(AV17/AW17)+AY17 -> 14.956311 | BW17: H | BY17: H | CA17: H | CH17: 712 | CJ17: =G17 -> 10704833 | CK17: 0020 | CL17: =E17 -> 552181 | CM17: =F17 -> BC28-0090-D-APH-5180-3538-PP-6 NOTCHES | CN17: =AQ17 -> 05.08.2026 | CO17: =AR17 -> 06:00:00 | CP17: =AS17 -> 05.08.2026 | CQ17: =AT17 -> 18:00:00 | CR17: =ROUNDDOWN(AZ17,0) -> 10800 | CS17: =ROUNDDOWN(BA17,0) -> 40 | CT17: PCE | CV17: H | CX17: H | CZ17: H | DB17: H | DD17: H | DF17: H | DN17: =B17 -> A16 | DO17: =F17 -> BC28-0090-D-APH-5180-3538-PP-6 NOTCHES | DP17: =(3600/AC17)*I17*12*0.98 -> 9408 | DQ17: =P17 -> 5172 | DR17: =DQ17/DP17*100 -> 54.97449 | DS17: =Y17 -> 0.6 | DT17: =Z17 -> 0.0078917878 | DU17: =SUM(AG17:AI17) -> 0 | DV17: =SUM(AD17:AF17) -> 0 | DW17: =Y17+W17+AM17+AN17/U17*100 -> 0.6 | DY17: =AJ17 -> Stop 1pm.Change mtrl PCR.
A18: 5M | B18: A16 | C18: DIPAK | D18: =VLOOKUP(E18,'Reference Card '!A:E,5,FALSE) -> KingFa NC050 | E18: 666342 | F18: =VLOOKUP(E18,'[1]Reference Card '!A:B,2,FALSE) -> BC28-0090-D-APH-5180-3538-PCR | G18: 10704854 | H18: - | I18: =VLOOKUP(E18,'[1]Reference Card '!A:C,3,FALSE) -> 6 | J18: =VLOOKUP(E18,'[1]Reference Card '!A:H,8,FALSE) -> 14.7 | K18: =VLOOKUP(E18,'[1]Reference Card '!A:F,6,FALSE) -> 14.7 | L18: 0 | M18: 108000 | N18: 0 | O18: 0 | P18: =L18*I18 -> 0 | Q18: 0 | R18: =(Q18*K18)/1000 -> 0 | S18: 0 | T18: =IF(M18="Sample","-",IF(M18="RTFN","-",M18-S18)) -> 108000 | U18: =(P18*K18)/1000 -> 0 | V18: =(J18-K18)*P18/1000 -> 0 | W18: 21 | X18: =W18/U18 -> #DIV/0! | Y18: 0 | Z18: =Y18/U18 -> #DIV/0! | AA18: 29 | AB18: =AA18/3600*L18 -> 0 | AC18: =VLOOKUP(E18,'[2]Reference Card '!A:I,9,FALSE) -> 27 | AH18: 5 | AJ18: Under tech.Thickness. | AO18: =(U18-R18-W18-Y18-AM18-AN18)-(O18*K18/1000) -> -21 | AP18: Morning | AQ18: 05.08.2026 | AR18: 06:00:00 | AS18: 05.08.2026 | AT18: 18:00:00 | AU18: =(Y18+W18+AM18+AN18)*1000/K18 -> 1428.5714 | AV18: =Q18+AU18 -> 1428.5714 | AW18: =3600/AA18*I18 -> 744.82759 | AX18: =(AV18/AW18)+AY18 -> 6.9179894 | AY18: =AG18+AH18+AI18 -> 5 | AZ18: =Q18 -> 0 | BA18: =AU18 -> 1428.5714 | BB18: =BA18/AZ18 -> #DIV/0! | BC18: 712 | BE18: =G18 -> 10704854 | BF18: 0010 | BG18: =E18 -> 666342 | BH18: =F18 -> BC28-0090-D-APH-5180-3538-PCR | BI18: =AQ18 -> 05.08.2026 | BJ18: =AR18 -> 06:00:00 | BK18: =AS18 -> 05.08.2026 | BL18: =AT18 -> 18:00:00 | BM18: =ROUNDDOWN(Q18+AU18,0) -> 1428 | BN18: 0 | BO18: PCE | BQ18: H | BR18: =(AV18/AW18)+AY18 -> 6.9179894 | BS18: H | BT18: =(AV18/AW18)+AY18 -> 6.9179894 | BU18: H | BV18: =(AV18/AW18)+AY18 -> 6.9179894 | BW18: H | BY18: H | CA18: H | CH18: 712 | CJ18: =G18 -> 10704854 | CK18: 0020 | CL18: =E18 -> 666342 | CM18: =F18 -> BC28-0090-D-APH-5180-3538-PCR | CN18: =AQ18 -> 05.08.2026 | CO18: =AR18 -> 06:00:00 | CP18: =AS18 -> 05.08.2026 | CQ18: =AT18 -> 18:00:00 | CR18: =ROUNDDOWN(AZ18,0) -> 0 | CS18: =ROUNDDOWN(BA18,0) -> 1428 | CT18: PCE | CV18: H | CX18: H | CZ18: H | DB18: H | DD18: H | DF18: H | DN18: =B18 -> A16 | DO18: =F18 -> BC28-0090-D-APH-5180-3538-PCR | DP18: =(3600/AC18)*I18*12*0.98 -> 9408 | DQ18: =P18 -> 0 | DR18: =DQ18/DP18*100 -> 0 | DS18: =Y18 -> 0 | DT18: =Z18 -> #DIV/0! | DU18: =SUM(AG18:AI18) -> 5 | DV18: =SUM(AD18:AF18) -> 0 | DW18: =Y18+W18+AM18+AN18/U18*100 -> #DIV/0! | DY18: =AJ18 -> Under tech.Thickness.
A19: 5M | B19: A17 | C19: ZAM | D19: =VLOOKUP(E19,'Reference Card '!A:E,5,FALSE) -> PET RECRON | E19: 620599 | F19: =VLOOKUP(E19,'[1]Reference Card '!A:B,2,FALSE) -> BC28-0750-K4-R-CL (55g) | G19: 10703143 | H19: - | I19: =VLOOKUP(E19,'[1]Reference Card '!A:C,3,FALSE) -> 4 | J19: =VLOOKUP(E19,'[1]Reference Card '!A:H,8,FALSE) -> 55 | K19: =VLOOKUP(E19,'[1]Reference Card '!A:F,6,FALSE) -> 55 | L19: 1436 | M19: 72000 | N19: 675 | O19: 900 | P19: =L19*I19 -> 5744 | Q19: 5400 | R19: =(Q19*K19)/1000 -> 297 | S19: 51300 | T19: =IF(M19="Sample","-",IF(M19="RTFN","-",M19-S19)) -> 20700 | U19: =(P19*K19)/1000 -> 315.92 | V19: =(J19-K19)*P19/1000 -> 0 | W19: 0 | X19: =W19/U19 -> 0 | Y19: 6.2 | Z19: =Y19/U19 -> 0.019625222 | AA19: 29.2 | AB19: =AA19/3600*L19 -> 11.647556 | AC19: =VLOOKUP(E19,'[2]Reference Card '!A:I,9,FALSE) -> 28 | AJ19: Black dot.L.test. | AM19: 5 | AN19: 6 | AO19: =(U19-R19-W19-Y19-AM19-AN19)-(O19*K19/1000) -> -47.78 | AP19: Morning | AQ19: 05.08.2026 | AR19: 06:00:00 | AS19: 05.08.2026 | AT19: 18:00:00 | AU19: =(Y19+W19+AM19+AN19)*1000/K19 -> 312.72727 | AV19: =Q19+AU19 -> 5712.7273 | AW19: =3600/AA19*I19 -> 493.15068 | AX19: =(AV19/AW19)+AY19 -> 11.584141 | AY19: =AG19+AH19+AI19 -> 0 | AZ19: =Q19 -> 5400 | BA19: =AU19 -> 312.72727 | BB19: =BA19/AZ19 -> 0.057912458 | BC19: 712 | BE19: =G19 -> 10703143 | BF19: 0010 | BG19: =E19 -> 620599 | BH19: =F19 -> BC28-0750-K4-R-CL (55g) | BI19: =AQ19 -> 05.08.2026 | BJ19: =AR19 -> 06:00:00 | BK19: =AS19 -> 05.08.2026 | BL19: =AT19 -> 18:00:00 | BM19: =ROUNDDOWN(Q19+AU19,0) -> 5712 | BN19: 0 | BO19: PCE | BQ19: H | BR19: =(AV19/AW19)+AY19 -> 11.584141 | BS19: H | BT19: =(AV19/AW19)+AY19 -> 11.584141 | BU19: H | BV19: =(AV19/AW19)+AY19 -> 11.584141 | BW19: H | BY19: H | CA19: H | CH19: 712 | CJ19: =G19 -> 10703143 | CK19: 0020 | CL19: =E19 -> 620599 | CM19: =F19 -> BC28-0750-K4-R-CL (55g) | CN19: =AQ19 -> 05.08.2026 | CO19: =AR19 -> 06:00:00 | CP19: =AS19 -> 05.08.2026 | CQ19: =AT19 -> 18:00:00 | CR19: =ROUNDDOWN(AZ19,0) -> 5400 | CS19: =ROUNDDOWN(BA19,0) -> 312 | CT19: PCE | CV19: H | CX19: H | CZ19: H | DB19: H | DD19: H | DF19: H | DN19: =B19 -> A17 | DO19: =F19 -> BC28-0750-K4-R-CL (55g) | DP19: =(3600/AC19)*I19*12*0.98 -> 6048 | DQ19: =P19 -> 5744 | DR19: =DQ19/DP19*100 -> 94.973545 | DS19: =Y19 -> 6.2 | DT19: =Z19 -> 0.019625222 | DU19: =SUM(AG19:AI19) -> 0 | DV19: =SUM(AD19:AF19) -> 0 | DW19: =Y19+W19+AM19+AN19/U19*100 -> 13.099215 | DY19: =AJ19 -> Black dot.L.test.
A20: 5M | B20: A18 | C20: DIPAK | D20: =VLOOKUP(E20,'Reference Card '!A:E,5,FALSE) -> KingFa NC050 | E20: 666344 | F20: =VLOOKUP(E20,'[1]Reference Card '!A:B,2,FALSE) -> BC28-0056-D-APH-5040-0756-PCR | G20: 10703144 | H20: - | I20: =VLOOKUP(E20,'[1]Reference Card '!A:C,3,FALSE) -> 6 | J20: 12.3 | K20: 12.3 | L20: 1548 | M20: 162000 | N20: 810 | O20: 1620 | P20: =L20*I20 -> 9288 | Q20: 8100 | R20: =(Q20*K20)/1000 -> 99.63 | S20: 98820 | T20: =IF(M20="Sample","-",IF(M20="RTFN","-",M20-S20)) -> 63180 | U20: =(P20*K20)/1000 -> 114.2424 | V20: =(J20-K20)*P20/1000 -> 0 | W20: 0 | X20: =W20/U20 -> 0 | Y20: 4.5 | Z20: =Y20/U20 -> 0.039389929 | AA20: 27.4 | AB20: =AA20/3600*L20 -> 11.782 | AC20: =VLOOKUP(E20,'[2]Reference Card '!A:I,9,FALSE) -> 26 | AJ20: Drooling..L.test. | AM20: 1 | AN20: 2 | AO20: =(U20-R20-W20-Y20-AM20-AN20)-(O20*K20/1000) -> -12.8136 | AP20: Morning | AQ20: 05.08.2026 | AR20: 06:00:00 | AS20: 05.08.2026 | AT20: 18:00:00 | AU20: =(Y20+W20+AM20+AN20)*1000/K20 -> 609.7561 | AV20: =Q20+AU20 -> 8709.7561 | AW20: =3600/AA20*I20 -> 788.32117 | AX20: =(AV20/AW20)+AY20 -> 11.048487 | AY20: =AG20+AH20+AI20 -> 0 | AZ20: =Q20 -> 8100 | BA20: =AU20 -> 609.7561 | BB20: =BA20/AZ20 -> 0.075278531 | BC20: 712 | BE20: =G20 -> 10703144 | BF20: 0010 | BG20: =E20 -> 666344 | BH20: =F20 -> BC28-0056-D-APH-5040-0756-PCR | BI20: =AQ20 -> 05.08.2026 | BJ20: =AR20 -> 06:00:00 | BK20: =AS20 -> 05.08.2026 | BL20: =AT20 -> 18:00:00 | BM20: =ROUNDDOWN(Q20+AU20,0) -> 8709 | BN20: 0 | BO20: PCE | BQ20: H | BR20: =(AV20/AW20)+AY20 -> 11.048487 | BS20: H | BT20: =(AV20/AW20)+AY20 -> 11.048487 | BU20: H | BV20: =(AV20/AW20)+AY20 -> 11.048487 | BW20: H | BY20: H | CA20: H | CH20: 712 | CJ20: =G20 -> 10703144 | CK20: 0020 | CL20: =E20 -> 666344 | CM20: =F20 -> BC28-0056-D-APH-5040-0756-PCR | CN20: =AQ20 -> 05.08.2026 | CO20: =AR20 -> 06:00:00 | CP20: =AS20 -> 05.08.2026 | CQ20: =AT20 -> 18:00:00 | CR20: =ROUNDDOWN(AZ20,0) -> 8100 | CS20: =ROUNDDOWN(BA20,0) -> 609 | CT20: PCE | CV20: H | CX20: H | CZ20: H | DB20: H | DD20: H | DF20: H | DN20: =B20 -> A18 | DO20: =F20 -> BC28-0056-D-APH-5040-0756-PCR | DP20: =(3600/AC20)*I20*12*0.98 -> 9769.8462 | DQ20: =P20 -> 9288 | DR20: =DQ20/DP20*100 -> 95.068027 | DS20: =Y20 -> 4.5 | DT20: =Z20 -> 0.039389929 | DU20: =SUM(AG20:AI20) -> 0 | DV20: =SUM(AD20:AF20) -> 0 | DW20: =Y20+W20+AM20+AN20/U20*100 -> 7.2506635 | DY20: =AJ20 -> Drooling..L.test.
A21: 5M | B21: A19 | C21: WIYAH/SHAHID | D21: =VLOOKUP(E21,'Reference Card '!A:E,5,FALSE) -> PET | E21: 541381 | F21: =VLOOKUP(E21,'[1]Reference Card '!A:B,2,FALSE) -> BC28-1200-K-R-CL | G21: 10700742 | H21: - | I21: =VLOOKUP(E21,'[1]Reference Card '!A:C,3,FALSE) -> 4 | J21: =VLOOKUP(E21,'[1]Reference Card '!A:H,8,FALSE) -> 55 | K21: =VLOOKUP(E21,'[1]Reference Card '!A:F,6,FALSE) -> 55 | L21: 44 | M21: 84000 | N21: 0 | O21: 175 | P21: =L21*I21 -> 176 | Q21: 0 | R21: =(Q21*K21)/1000 -> 0 | S21: 47775 | T21: =IF(M21="Sample","-",IF(M21="RTFN","-",M21-S21)) -> 36225 | U21: =(P21*K21)/1000 -> 9.68 | V21: =(J21-K21)*P21/1000 -> 0 | W21: 35.8 | X21: =W21/U21 -> 3.6983471 | Y21: 0 | Z21: =Y21/U21 -> 0 | AA21: 29.9 | AB21: =AA21/3600*L21 -> 0.36544444 | AC21: =VLOOKUP(E21,'[2]Reference Card '!A:I,9,FALSE) -> 30.08 | AH21: 11.5 | AJ21: Under tech.Thickness.Start 5.30pm. | AM21: 22 | AN21: 13 | AO21: =(U21-R21-W21-Y21-AM21-AN21)-(O21*K21/1000) -> -70.745 | AP21: Morning | AQ21: 05.08.2026 | AR21: 06:00:00 | AS21: 05.08.2026 | AT21: 18:00:00 | AU21: =(Y21+W21+AM21+AN21)*1000/K21 -> 1287.2727 | AV21: =Q21+AU21 -> 1287.2727 | AW21: =3600/AA21*I21 -> 481.60535 | AX21: =(AV21/AW21)+AY21 -> 14.172879 | AY21: =AG21+AH21+AI21 -> 11.5 | AZ21: =Q21 -> 0 | BA21: =AU21 -> 1287.2727 | BB21: =BA21/AZ21 -> #DIV/0! | BC21: 712 | BE21: =G21 -> 10700742 | BF21: 0010 | BG21: =E21 -> 541381 | BH21: =F21 -> BC28-1200-K-R-CL | BI21: =AQ21 -> 05.08.2026 | BJ21: =AR21 -> 06:00:00 | BK21: =AS21 -> 05.08.2026 | BL21: =AT21 -> 18:00:00 | BM21: =ROUNDDOWN(Q21+AU21,0) -> 1287 | BN21: 0 | BO21: PCE | BQ21: H | BR21: =(AV21/AW21)+AY21 -> 14.172879 | BS21: H | BT21: =(AV21/AW21)+AY21 -> 14.172879 | BU21: H | BV21: =(AV21/AW21)+AY21 -> 14.172879 | BW21: H | BY21: H | CA21: H | CH21: 712 | CJ21: =G21 -> 10700742 | CK21: 0020 | CL21: =E21 -> 541381 | CM21: =F21 -> BC28-1200-K-R-CL | CN21: =AQ21 -> 05.08.2026 | CO21: =AR21 -> 06:00:00 | CP21: =AS21 -> 05.08.2026 | CQ21: =AT21 -> 18:00:00 | CR21: =ROUNDDOWN(AZ21,0) -> 0 | CS21: =ROUNDDOWN(BA21,0) -> 1287 | CT21: PCE | CV21: H | CX21: H | CZ21: H | DB21: H | DD21: H | DF21: H | DN21: =B21 -> A19 | DO21: =F21 -> BC28-1200-K-R-CL | DP21: =(3600/AC21)*I21*12*0.98 -> 5629.7872 | DQ21: =P21 -> 176 | DR21: =DQ21/DP21*100 -> 3.1262283 | DS21: =Y21 -> 0 | DT21: =Z21 -> 0 | DU21: =SUM(AG21:AI21) -> 11.5 | DV21: =SUM(AD21:AF21) -> 0 | DW21: =Y21+W21+AM21+AN21/U21*100 -> 192.09752 | DY21: =AJ21 -> Under tech.Thickness.Start 5.30pm.
A22: 5M | B22: A21 | C22: DIPAK | D22: =VLOOKUP(E22,'Reference Card '!A:E,5,FALSE) -> KingFa NC050 | E22: 666342 | F22: =VLOOKUP(E22,'[1]Reference Card '!A:B,2,FALSE) -> BC28-0090-D-APH-5180-3538-PCR | G22: 10704701 | H22: - | I22: =VLOOKUP(E22,'[1]Reference Card '!A:C,3,FALSE) -> 6 | J22: =VLOOKUP(E22,'[1]Reference Card '!A:H,8,FALSE) -> 14.7 | K22: =VLOOKUP(E22,'[1]Reference Card '!A:F,6,FALSE) -> 14.7 | L22: 1266 | M22: 108000 | N22: 1350 | O22: 2970 | P22: =L22*I22 -> 7596 | Q22: 5400 | R22: =(Q22*K22)/1000 -> 79.38 | S22: 19170 | T22: =IF(M22="Sample","-",IF(M22="RTFN","-",M22-S22)) -> 88830 | U22: =(P22*K22)/1000 -> 111.6612 | V22: =(J22-K22)*P22/1000 -> 0 | W22: 0 | X22: =W22/U22 -> 0 | Y22: 8.6 | Z22: =Y22/U22 -> 0.077018696 | AA22: 29 | AB22: =AA22/3600*L22 -> 10.198333 | AC22: =VLOOKUP(E22,'[2]Reference Card '!A:I,9,FALSE) -> 27 | AH22: 1.8 | AJ22: Often mc stop sometimes bottle stuck & dented.L.test. | AM22: 2 | AN22: 2 | AO22: =(U22-R22-W22-Y22-AM22-AN22)-(O22*K22/1000) -> -23.9778 | AP22: Morning | AQ22: 05.08.2026 | AR22: 06:00:00 | AS22: 05.08.2026 | AT22: 18:00:00 | AU22: =(Y22+W22+AM22+AN22)*1000/K22 -> 857.14286 | AV22: =Q22+AU22 -> 6257.1429 | AW22: =3600/AA22*I22 -> 744.82759 | AX22: =(AV22/AW22)+AY22 -> 10.200794 | AY22: =AG22+AH22+AI22 -> 1.8 | AZ22: =Q22 -> 5400 | BA22: =AU22 -> 857.14286 | BB22: =BA22/AZ22 -> 0.15873016 | BC22: 712 | BE22: =G22 -> 10704701 | BF22: 0010 | BG22: =E22 -> 666342 | BH22: =F22 -> BC28-0090-D-APH-5180-3538-PCR | BI22: =AQ22 -> 05.08.2026 | BJ22: =AR22 -> 06:00:00 | BK22: =AS22 -> 05.08.2026 | BL22: =AT22 -> 18:00:00 | BM22: =ROUNDDOWN(Q22+AU22,0) -> 6257 | BN22: 0 | BO22: PCE | BQ22: H | BR22: =(AV22/AW22)+AY22 -> 10.200794 | BS22: H | BT22: =(AV22/AW22)+AY22 -> 10.200794 | BU22: H | BV22: =(AV22/AW22)+AY22 -> 10.200794 | BW22: H | BY22: H | CA22: H | CH22: 712 | CJ22: =G22 -> 10704701 | CK22: 0020 | CL22: =E22 -> 666342 | CM22: =F22 -> BC28-0090-D-APH-5180-3538-PCR | CN22: =AQ22 -> 05.08.2026 | CO22: =AR22 -> 06:00:00 | CP22: =AS22 -> 05.08.2026 | CQ22: =AT22 -> 18:00:00 | CR22: =ROUNDDOWN(AZ22,0) -> 5400 | CS22: =ROUNDDOWN(BA22,0) -> 857 | CT22: PCE | CV22: H | CX22: H | CZ22: H | DB22: H | DD22: H | DF22: H | DN22: =B22 -> A21 | DO22: =F22 -> BC28-0090-D-APH-5180-3538-PCR | DP22: =(3600/AC22)*I22*12*0.98 -> 9408 | DQ22: =P22 -> 7596 | DR22: =DQ22/DP22*100 -> 80.739796 | DS22: =Y22 -> 8.6 | DT22: =Z22 -> 0.077018696 | DU22: =SUM(AG22:AI22) -> 1.8 | DV22: =SUM(AD22:AF22) -> 0 | DW22: =Y22+W22+AM22+AN22/U22*100 -> 12.391132 | DY22: =AJ22 -> Often mc stop sometimes bottle stuck & dented.L.test.
A23: 5M | B23: A23 | C23: MOHID | D23: =VLOOKUP(E23,'Reference Card '!A:E,5,FALSE) -> PPSB520Y | E23: 550077 | F23: =VLOOKUP(E23,'[1]Reference Card '!A:B,2,FALSE) -> BC28-0170-D-APH-5040-0736-PP-6NOTCHES(NO LOGO) | G23: 10704309 | H23: - | I23: =VLOOKUP(E23,'[1]Reference Card '!A:C,3,FALSE) -> 6 | J23: 28 | K23: 28 | L23: 933 | M23: 67200 | N23: 4536 | O23: 0 | P23: =L23*I23 -> 5598 | Q23: 10080 | R23: =(Q23*K23)/1000 -> 282.24 | S23: 10080 | T23: =IF(M23="Sample","-",IF(M23="RTFN","-",M23-S23)) -> 57120 | U23: =(P23*K23)/1000 -> 156.744 | V23: =(J23-K23)*P23/1000 -> 0 | W23: 0 | X23: =W23/U23 -> 0 | Y23: 1.5 | Z23: =Y23/U23 -> 0.0095697443 | AA23: 44.3 | AB23: =AA23/3600*L23 -> 11.481083 | AC23: =VLOOKUP(E23,'[2]Reference Card '!A:I,9,FALSE) -> 42 | AJ23: Base scratches.L.test. | AM23: 10 | AN23: 12 | AO23: =(U23-R23-W23-Y23-AM23-AN23)-(O23*K23/1000) -> -148.996 | AP23: Morning | AQ23: 05.08.2026 | AR23: 06:00:00 | AS23: 05.08.2026 | AT23: 18:00:00 | AU23: =(Y23+W23+AM23+AN23)*1000/K23 -> 839.28571 | AV23: =Q23+AU23 -> 10919.286 | AW23: =3600/AA23*I23 -> 487.58465 | AX23: =(AV23/AW23)+AY23 -> 22.394646 | AY23: =AG23+AH23+AI23 -> 0 | AZ23: =Q23 -> 10080 | BA23: =AU23 -> 839.28571 | BB23: =BA23/AZ23 -> 0.083262472 | BC23: 712 | BE23: =G23 -> 10704309 | BF23: 0010 | BG23: =E23 -> 550077 | BH23: =F23 -> BC28-0170-D-APH-5040-0736-PP-6NOTCHES(NO LOGO) | BI23: =AQ23 -> 05.08.2026 | BJ23: =AR23 -> 06:00:00 | BK23: =AS23 -> 05.08.2026 | BL23: =AT23 -> 18:00:00 | BM23: =ROUNDDOWN(Q23+AU23,0) -> 10919 | BN23: 0 | BO23: PCE | BQ23: H | BR23: =(AV23/AW23)+AY23 -> 22.394646 | BS23: H | BT23: =(AV23/AW23)+AY23 -> 22.394646 | BU23: H | BV23: =(AV23/AW23)+AY23 -> 22.394646 | BW23: H | BY23: H | CA23: H | CH23: 712 | CJ23: =G23 -> 10704309 | CK23: 0020 | CL23: =E23 -> 550077 | CM23: =F23 -> BC28-0170-D-APH-5040-0736-PP-6NOTCHES(NO LOGO) | CN23: =AQ23 -> 05.08.2026 | CO23: =AR23 -> 06:00:00 | CP23: =AS23 -> 05.08.2026 | CQ23: =AT23 -> 18:00:00 | CR23: =ROUNDDOWN(AZ23,0) -> 10080 | CS23: =ROUNDDOWN(BA23,0) -> 839 | CT23: PCE | CV23: H | CX23: H | CZ23: H | DB23: H | DD23: H | DF23: H | DN23: =B23 -> A23 | DO23: =F23 -> BC28-0170-D-APH-5040-0736-PP-6NOTCHES(NO LOGO) | DP23: =(3600/AC23)*I23*12*0.98 -> 6048 | DQ23: =P23 -> 5598 | DR23: =DQ23/DP23*100 -> 92.559524 | DS23: =Y23 -> 1.5 | DT23: =Z23 -> 0.0095697443 | DU23: =SUM(AG23:AI23) -> 0 | DV23: =SUM(AD23:AF23) -> 0 | DW23: =Y23+W23+AM23+AN23/U23*100 -> 19.155795 | DY23: =AJ23 -> Base scratches.L.test.
A24: 5M | B24: KM16 | C24: KAIMULLAH | D24: =VLOOKUP(E24,'Reference Card '!A:E,5,FALSE) -> HDPE5403A+LDPE265YZ | E24: 453933 | F24: =VLOOKUP(E24,'[1]Reference Card '!A:B,2,FALSE) -> EBK38-0500-K-Q-YL-PE(S0576) | G24: 10704265 | H24: - | I24: =VLOOKUP(E24,'[1]Reference Card '!A:C,3,FALSE) -> 2 | J24: =VLOOKUP(E24,'[1]Reference Card '!A:H,8,FALSE) -> 59 | K24: =VLOOKUP(E24,'[1]Reference Card '!A:F,6,FALSE) -> 39.5 | L24: 1804 | M24: 40320 | N24: 0 | O24: 360 | P24: =L24*I24 -> 3608 | Q24: 2880 | R24: =(Q24*K24)/1000 -> 113.76 | S24: 7560 | T24: =IF(M24="Sample","-",IF(M24="RTFN","-",M24-S24)) -> 32760 | U24: =(P24*K24)/1000 -> 142.516 | V24: =(J24-K24)*P24/1000 -> 70.356 | W24: 0 | X24: =W24/U24 -> 0 | Y24: 14.7 | Z24: =Y24/U24 -> 0.10314631 | AA24: 23.1 | AB24: =AA24/3600*L24 -> 11.575667 | AC24: =VLOOKUP(E24,'[2]Reference Card '!A:I,9,FALSE) -> 21.2 | AJ24: Line mark & b.dot.L.test. | AO24: =(U24-R24-W24-Y24-AM24-AN24)-(N69*K24/1000) -> 14.056 | AP24: Morning | AQ24: 05.08.2026 | AR24: 06:00:00 | AS24: 05.08.2026 | AT24: 18:00:00 | AU24: =(Y24+W24+AM24+AN24)*1000/K24 -> 372.1519 | AV24: =Q24+AU24 -> 3252.1519 | AW24: =3600/AA24*I24 -> 311.68831 | AX24: =(AV24/AW24)+AY24 -> 10.433987 | AY24: =AG24+AH24+AI24 -> 0 | AZ24: =Q24 -> 2880 | BA24: =AU24 -> 372.1519 | BB24: =BA24/AZ24 -> 0.12921941 | BC24: 712 | BE24: =G24 -> 10704265 | BF24: 0010 | BG24: =E24 -> 453933 | BH24: =F24 -> EBK38-0500-K-Q-YL-PE(S0576) | BI24: =AQ24 -> 05.08.2026 | BJ24: =AR24 -> 06:00:00 | BK24: =AS24 -> 05.08.2026 | BL24: =AT24 -> 18:00:00 | BM24: =ROUNDDOWN(Q24+AU24,0) -> 3252 | BN24: 0 | BO24: PCE | BQ24: H | BR24: =(AV24/AW24)+AY24 -> 10.433987 | BS24: H | BT24: =(AV24/AW24)+AY24 -> 10.433987 | BU24: H | BV24: =(AV24/AW24)+AY24 -> 10.433987 | BW24: H | BY24: H | CA24: H | CH24: 712 | CJ24: =G24 -> 10704265 | CK24: 0020 | CL24: =E24 -> 453933 | CM24: =F24 -> EBK38-0500-K-Q-YL-PE(S0576) | CN24: =AQ24 -> 05.08.2026 | CO24: =AR24 -> 06:00:00 | CP24: =AS24 -> 05.08.2026 | CQ24: =AT24 -> 18:00:00 | CR24: =ROUNDDOWN(AZ24,0) -> 2880 | CS24: =ROUNDDOWN(BA24,0) -> 372 | CT24: PCE | CV24: H | CX24: H | CZ24: H | DB24: H | DD24: H | DF24: H | DN24: =B24 -> KM16 | DO24: =F24 -> EBK38-0500-K-Q-YL-PE(S0576) | DP24: =(3600/AC24)*I24*12*0.98 -> 3993.9623 | DQ24: =P24 -> 3608 | DR24: =DQ24/DP24*100 -> 90.336357 | DS24: =Y24 -> 14.7 | DT24: =Z24 -> 0.10314631 | DU24: =SUM(AG24:AI24) -> 0 | DV24: =SUM(AD24:AF24) -> 0 | DW24: =Y24+W24+AM24+AN24/U24*100 -> 14.7 | DY24: =AJ24 -> Line mark & b.dot.L.test.
A25: 5M | B25: KM17 | C25: NITESH | D25: =VLOOKUP(E25,'Reference Card '!A:E,5,FALSE) -> MARLEX6007 | E25: 573943 | F25: =VLOOKUP(E25,'[1]Reference Card '!A:B,2,FALSE) -> EBK38-2000-K-S-WH-PE(S2012) | G25: 10702422 | H25: - | I25: =VLOOKUP(E25,'[1]Reference Card '!A:C,3,FALSE) -> 1 | J25: =VLOOKUP(E25,'[1]Reference Card '!A:H,8,FALSE) -> 180 | K25: =VLOOKUP(E25,'[1]Reference Card '!A:F,6,FALSE) -> 122 | L25: 1262 | M25: 20160 | N25: 315 | O25: 65 | P25: =L25*I25 -> 1262 | Q25: 1440 | R25: =(Q25*K25)/1000 -> 175.68 | S25: 15185 | T25: =IF(M25="Sample","-",IF(M25="RTFN","-",M25-S25)) -> 4975 | U25: =(P25*K25)/1000 -> 153.964 | V25: =(J25-K25)*P25/1000 -> 73.196 | W25: 0 | X25: =W25/U25 -> 0 | Y25: 8.7 | Z25: =Y25/U25 -> 0.056506716 | AA25: 33.8 | AB25: =AA25/3600*L25 -> 11.848778 | AC25: 35 | AJ25: Black dot.L.test | AO25: =(U25-R25-W25-Y25-AM25-AN25)-(O25*K25/1000) -> -38.346 | AP25: Morning | AQ25: 05.08.2026 | AR25: 06:00:00 | AS25: 05.08.2026 | AT25: 18:00:00 | AU25: =(Y25+W25+AM25+AN25)*1000/K25 -> 71.311475 | AV25: =Q25+AU25 -> 1511.3115 | AW25: =3600/AA25*I25 -> 106.50888 | AX25: =(AV25/AW25)+AY25 -> 14.189536 | AY25: =AG25+AH25+AI25 -> 0 | AZ25: =Q25 -> 1440 | BA25: =AU25 -> 71.311475 | BB25: =BA25/AZ25 -> 0.049521858 | BC25: 712 | BE25: =G25 -> 10702422 | BF25: 0010 | BG25: =E25 -> 573943 | BH25: =F25 -> EBK38-2000-K-S-WH-PE(S2012) | BI25: =AQ25 -> 05.08.2026 | BJ25: =AR25 -> 06:00:00 | BK25: =AS25 -> 05.08.2026 | BL25: =AT25 -> 18:00:00 | BM25: =ROUNDDOWN(Q25+AU25,0) -> 1511 | BN25: 0 | BO25: PCE | BQ25: H | BR25: =(AV25/AW25)+AY25 -> 14.189536 | BS25: H | BT25: =(AV25/AW25)+AY25 -> 14.189536 | BU25: H | BV25: =(AV25/AW25)+AY25 -> 14.189536 | BW25: H | BY25: H | CA25: H | CH25: 712 | CJ25: =G25 -> 10702422 | CK25: 0020 | CL25: =E25 -> 573943 | CM25: =F25 -> EBK38-2000-K-S-WH-PE(S2012) | CN25: =AQ25 -> 05.08.2026 | CO25: =AR25 -> 06:00:00 | CP25: =AS25 -> 05.08.2026 | CQ25: =AT25 -> 18:00:00 | CR25: =ROUNDDOWN(AZ25,0) -> 1440 | CS25: =ROUNDDOWN(BA25,0) -> 71 | CT25: PCE | CV25: H | CX25: H | CZ25: H | DB25: H | DD25: H | DF25: H | DN25: =B25 -> KM17 | DO25: =F25 -> EBK38-2000-K-S-WH-PE(S2012) | DP25: =(3600/AC25)*I25*12*0.98 -> 1209.6 | DQ25: =P25 -> 1262 | DR25: =DQ25/DP25*100 -> 104.33201 | DS25: =Y25 -> 8.7 | DT25: =Z25 -> 0.056506716 | DU25: =SUM(AG25:AI25) -> 0 | DV25: =SUM(AD25:AF25) -> 0 | DW25: =Y25+W25+AM25+AN25/U25*100 -> 8.7 | DY25: =AJ25 -> Black dot.L.test
A26: 5M | B26: KM25 | C26: NA | D26: =VLOOKUP(E26,'Reference Card '!A:E,5,FALSE) -> MARLEX6007 | E26: 618592 | F26: =VLOOKUP(E26,'[1]Reference Card '!A:B,2,FALSE) -> E22-0150-R-GY-HDPE | G26: 10701479 | H26: - | I26: =VLOOKUP(E26,'[1]Reference Card '!A:C,3,FALSE) -> 4 | J26: =VLOOKUP(E26,'[1]Reference Card '!A:H,8,FALSE) -> 26 | K26: =VLOOKUP(E26,'[1]Reference Card '!A:F,6,FALSE) -> 15 | L26: 0 | M26: 43200 | N26: 0 | O26: 0 | P26: =L26*I26 -> 0 | Q26: 0 | R26: =(Q26*K26)/1000 -> 0 | S26: 0 | T26: =IF(M26="Sample","-",IF(M26="RTFN","-",M26-S26)) -> 43200 | U26: =(P26*K26)/1000 -> 0 | V26: =(J26-K26)*P26/1000 -> 0 | W26: 18.6 | X26: =W26/U26 -> #DIV/0! | Y26: 0 | Z26: =Y26/U26 -> #DIV/0! | AA26: 24.3 | AB26: =AA26/3600*L26 -> 0 | AC26: =VLOOKUP(E26,'[2]Reference Card '!A:I,9,FALSE) -> 25 | AH26: 12 | AJ26: under tech.Top load out spec. | AM26: 5 | AO26: =(U26-R26-W26-Y26-AM26-AN26)-(O26*K26/1000) -> -23.6 | AP26: Morning | AQ26: 05.08.2026 | AR26: 06:00:00 | AS26: 05.08.2026 | AT26: 18:00:00 | AU26: =(Y26+W26+AM26+AN26)*1000/K26 -> 1573.3333 | AV26: =Q26+AU26 -> 1573.3333 | AW26: =3600/AA26*I26 -> 592.59259 | AX26: =(AV26/AW26)+AY26 -> 14.655 | AY26: =AG26+AH26+AI26 -> 12 | AZ26: =Q26 -> 0 | BA26: =AU26 -> 1573.3333 | BB26: =BA26/AZ26 -> #DIV/0! | BC26: 712 | BE26: =G26 -> 10701479 | BF26: 0010 | BG26: =E26 -> 618592 | BH26: =F26 -> E22-0150-R-GY-HDPE | BI26: =AQ26 -> 05.08.2026 | BJ26: =AR26 -> 06:00:00 | BK26: =AS26 -> 05.08.2026 | BL26: =AT26 -> 18:00:00 | BM26: =ROUNDDOWN(Q26+AU26,0) -> 1573 | BN26: 0 | BO26: PCE | BQ26: H | BR26: =(AV26/AW26)+AY26 -> 14.655 | BS26: H | BT26: =(AV26/AW26)+AY26 -> 14.655 | BU26: H | BV26: =(AV26/AW26)+AY26 -> 14.655 | BW26: H | BY26: H | CA26: H | CH26: 712 | CJ26: =G26 -> 10701479 | CK26: 0020 | CL26: =E26 -> 618592 | CM26: =F26 -> E22-0150-R-GY-HDPE | CN26: =AQ26 -> 05.08.2026 | CO26: =AR26 -> 06:00:00 | CP26: =AS26 -> 05.08.2026 | CQ26: =AT26 -> 18:00:00 | CR26: =ROUNDDOWN(AZ26,0) -> 0 | CS26: =ROUNDDOWN(BA26,0) -> 1573 | CT26: PCE | CV26: H | CX26: H | CZ26: H | DB26: H | DD26: H | DF26: H | DN26: =B26 -> KM25 | DO26: =F26 -> E22-0150-R-GY-HDPE | DP26: =(3600/AC26)*I26*12*0.98 -> 6773.76 | DQ26: =P26 -> 0 | DR26: =DQ26/DP26*100 -> 0 | DS26: =Y26 -> 0 | DT26: =Z26 -> #DIV/0! | DU26: =SUM(AG26:AI26) -> 12 | DV26: =SUM(AD26:AF26) -> 0 | DW26: =Y26+W26+AM26+AN26/U26*100 -> #DIV/0! | DY26: =AJ26 -> under tech.Top load out spec.
A27: 5M | B27: KM26 | C27: SHESHNATH | D27: =VLOOKUP(E27,'Reference Card '!A:E,5,FALSE) -> MARLEX6007 | E27: 617192 | F27: =VLOOKUP(E27,'[1]Reference Card '!A:B,2,FALSE) -> EBK38-2017-K-S-BEIGE-HDPE | G27: 10704222 | H27: - | I27: =VLOOKUP(E27,'[1]Reference Card '!A:C,3,FALSE) -> 1 | J27: =VLOOKUP(E27,'[1]Reference Card '!A:H,8,FALSE) -> 139.8 | K27: =VLOOKUP(E27,'[1]Reference Card '!A:F,6,FALSE) -> 103 | L27: 1217 | M27: 20328 | N27: 242 | O27: 396 | P27: =L27*I27 -> 1217 | Q27: 968 | R27: =(Q27*K27)/1000 -> 99.704 | S27: 8140 | T27: =IF(M27="Sample","-",IF(M27="RTFN","-",M27-S27)) -> 12188 | U27: =(P27*K27)/1000 -> 125.351 | V27: =(J27-K27)*P27/1000 -> 44.7856 | W27: 0 | X27: =W27/U27 -> 0 | Y27: 9.8 | Z27: =Y27/U27 -> 0.078180469 | AA27: 33 | AB27: =AA27/3600*L27 -> 11.155833 | AC27: =VLOOKUP(E27,'[2]Reference Card '!A:I,9,FALSE) -> 33 | AJ27: Line mark & black dot.l.test | AO27: =(U27-R27-W27-Y27-AM27-AN27)-(O27*K27/1000) -> -24.941 | AP27: Morning | AQ27: 05.08.2026 | AR27: 06:00:00 | AS27: 05.08.2026 | AT27: 18:00:00 | AU27: =(Y27+W27+AM27+AN27)*1000/K27 -> 95.145631 | AV27: =Q27+AU27 -> 1063.1456 | AW27: =3600/AA27*I27 -> 109.09091 | AX27: =(AV27/AW27)+AY27 -> 9.7455016 | AY27: =AG27+AH27+AI27 -> 0 | AZ27: =Q27 -> 968 | BA27: =AU27 -> 95.145631 | BB27: =BA27/AZ27 -> 0.098290941 | BC27: 712 | BE27: =G27 -> 10704222 | BF27: 0010 | BG27: =E27 -> 617192 | BH27: =F27 -> EBK38-2017-K-S-BEIGE-HDPE | BI27: =AQ27 -> 05.08.2026 | BJ27: =AR27 -> 06:00:00 | BK27: =AS27 -> 05.08.2026 | BL27: =AT27 -> 18:00:00 | BM27: =ROUNDDOWN(Q27+AU27,0) -> 1063 | BN27: 0 | BO27: PCE | BQ27: H | BR27: =(AV27/AW27)+AY27 -> 9.7455016 | BS27: H | BT27: =(AV27/AW27)+AY27 -> 9.7455016 | BU27: H | BV27: =(AV27/AW27)+AY27 -> 9.7455016 | BW27: H | BY27: H | CA27: H | CH27: 712 | CJ27: =G27 -> 10704222 | CK27: 0020 | CL27: =E27 -> 617192 | CM27: =F27 -> EBK38-2017-K-S-BEIGE-HDPE | CN27: =AQ27 -> 05.08.2026 | CO27: =AR27 -> 06:00:00 | CP27: =AS27 -> 05.08.2026 | CQ27: =AT27 -> 18:00:00 | CR27: =ROUNDDOWN(AZ27,0) -> 968 | CS27: =ROUNDDOWN(BA27,0) -> 95 | CT27: PCE | CV27: H | CX27: H | CZ27: H | DB27: H | DD27: H | DF27: H | DN27: =B27 -> KM26 | DO27: =F27 -> EBK38-2017-K-S-BEIGE-HDPE | DP27: =(3600/AC27)*I27*12*0.98 -> 1282.9091 | DQ27: =P27 -> 1217 | DR27: =DQ27/DP27*100 -> 94.862528 | DS27: =Y27 -> 9.8 | DT27: =Z27 -> 0.078180469 | DU27: =SUM(AG27:AI27) -> 0 | DV27: =SUM(AD27:AF27) -> 0 | DW27: =Y27+W27+AM27+AN27/U27*100 -> 9.8 | DY27: =AJ27 -> Line mark & black dot.l.test
A28: 5M | B28: B3 | C28: ASMULLAH | D28: =VLOOKUP(E28,'Reference Card '!A:E,5,FALSE) -> SM398 | E28: 606524 | F28: =VLOOKUP(E28,'[1]Reference Card '!A:B,2,FALSE) -> C35-R/S-F.TOP D.CHOC W SEAL 2.0 (ASEM) | G28: 10704266 | H28: - | I28: =VLOOKUP(E28,'[1]Reference Card '!A:C,3,FALSE) -> 12 | J28: =VLOOKUP(E28,'[1]Reference Card '!A:H,8,FALSE) -> 5.86 | K28: =VLOOKUP(E28,'[1]Reference Card '!A:F,6,FALSE) -> 5.86 | L28: 1247 | M28: 170000 | N28: 13600 | O28: 27200 | P28: =L28*I28 -> 14964 | Q28: 0 | R28: =(Q28*K28)/1000 -> 0 | S28: 95200 | T28: =IF(M28="Sample","-",IF(M28="RTFN","-",M28-S28)) -> 74800 | U28: =(P28*K28)/1000 -> 87.68904 | V28: =(J28-K28)*P28/1000 -> 0 | W28: 0 | X28: =W28/U28 -> 0 | Y28: 8.2 | Z28: =Y28/U28 -> 0.093512256 | AA28: 32.5 | AB28: =AA28/3600*L28 -> 11.257639 | AC28: =VLOOKUP(E28,'[2]Reference Card '!A:I,9,FALSE) -> 29.04 | AJ28: Uncapping & Shot moulding. | AO28: =(U28-R28-W28-Y28-AM28-AN28)-(O28*K28/1000) -> -79.90296 | AP28: Morning | AQ28: 05.08.2026 | AR28: 06:00:00 | AS28: 05.08.2026 | AT28: 18:00:00 | AU28: =(Y28+W28+AM28+AN28)*1000/K28 -> 1399.3174 | AV28: =Q28+AU28 -> 1399.3174 | AW28: =3600/AA28*I28 -> 1329.2308 | AX28: =(AV28/AW28)+AY28 -> 1.0527272 | AY28: =AG28+AH28+AI28 -> 0 | AZ28: =Q28 -> 0 | BA28: =AU28 -> 1399.3174 | BB28: =BA28/AZ28 -> #DIV/0! | BC28: 712 | BE28: =G28 -> 10704266 | BF28: 0010 | BG28: =E28 -> 606524 | BH28: =F28 -> C35-R/S-F.TOP D.CHOC W SEAL 2.0 (ASEM) | BI28: =AQ28 -> 05.08.2026 | BJ28: =AR28 -> 06:00:00 | BK28: =AS28 -> 05.08.2026 | BL28: =AT28 -> 18:00:00 | BM28: =ROUNDDOWN(Q28+AU28,0) -> 1399 | BN28: 0 | BO28: PCE | BQ28: H | BR28: =(AV28/AW28)+AY28 -> 1.0527272 | BS28: H | BT28: =(AV28/AW28)+AY28 -> 1.0527272 | BU28: H | BV28: =(AV28/AW28)+AY28 -> 1.0527272 | BW28: H | BY28: H | CA28: H | CH28: 712 | CJ28: =G28 -> 10704266 | CK28: 0020 | CL28: =E28 -> 606524 | CM28: =F28 -> C35-R/S-F.TOP D.CHOC W SEAL 2.0 (ASEM) | CN28: =AQ28 -> 05.08.2026 | CO28: =AR28 -> 06:00:00 | CP28: =AS28 -> 05.08.2026 | CQ28: =AT28 -> 18:00:00 | CR28: =ROUNDDOWN(AZ28,0) -> 0 | CS28: =ROUNDDOWN(BA28,0) -> 1399 | CT28: PCE | CV28: H | CX28: H | CZ28: H | DB28: H | DD28: H | DF28: H | DN28: =B28 -> B3 | DO28: =F28 -> C35-R/S-F.TOP D.CHOC W SEAL 2.0 (ASEM) | DP28: =(3600/AC28)*I28*12*0.98 -> 17494.215 | DQ28: =P28 -> 14964 | DR28: =DQ28/DP28*100 -> 85.536848 | DS28: =Y28 -> 8.2 | DT28: =Z28 -> 0.093512256 | DU28: =SUM(AG28:AI28) -> 0 | DV28: =SUM(AD28:AF28) -> 0 | DW28: =Y28+W28+AM28+AN28/U28*100 -> 8.2 | DY28: =AJ28 -> Uncapping & Shot moulding.
